Workbook

Sheet CO-PO mapping summary
C1: L. D. College of Engineering Ahmedabad
C2: Electrical Engineering Department: Sem - 3 (2025 - 26)
C3: Subject: BE03009011 - Analog and Digital Engineering
C6: Total Hours planned for CO's
C7: CO | D7: CO1 | E7: CO2 | F7: CO3 | G7: CO4 | H7: CO5 | I7: Total
C8: Th | D8: =SUMIFS(COPO_Th_Pr_Oth!$D$5:$D$111,COPO_Th_Pr_Oth!$C$5:$C$111,"Th",COPO_Th_Pr_Oth!E$5:E$111,"1") -> 45 | E8: =SUMIFS(COPO_Th_Pr_Oth!$D$5:$D$111,COPO_Th_Pr_Oth!$C$5:$C$111,"Th",COPO_Th_Pr_Oth!F$5:F$111,"1") -> 6 | F8: =SUMIFS(COPO_Th_Pr_Oth!$D$5:$D$111,COPO_Th_Pr_Oth!$C$5:$C$111,"Th",COPO_Th_Pr_Oth!G$5:G$111,"1") -> 6 | G8: =SUMIFS(COPO_Th_Pr_Oth!$D$5:$D$111,COPO_Th_Pr_Oth!$C$5:$C$111,"Th",COPO_Th_Pr_Oth!H$5:H$111,"1") -> 17 | H8: =SUMIFS(COPO_Th_Pr_Oth!$D$5:$D$111,COPO_Th_Pr_Oth!$C$5:$C$111,"Th",COPO_Th_Pr_Oth!I$5:I$111,"1") -> 8 | I8: =SUM(D8:H8) -> 82
C9: Lab | D9: =SUMIFS(COPO_Th_Pr_Oth!$D$5:$D$111,COPO_Th_Pr_Oth!$C$5:$C$111,"Pr",COPO_Th_Pr_Oth!E$5:E$111,"1") -> 14 | E9: =SUMIFS(COPO_Th_Pr_Oth!$D$5:$D$111,COPO_Th_Pr_Oth!$C$5:$C$111,"Pr",COPO_Th_Pr_Oth!F$5:F$111,"1") -> 4 | F9: =SUMIFS(COPO_Th_Pr_Oth!$D$5:$D$111,COPO_Th_Pr_Oth!$C$5:$C$111,"Pr",COPO_Th_Pr_Oth!G$5:G$111,"1") -> 6 | G9: =SUMIFS(COPO_Th_Pr_Oth!$D$5:$D$111,COPO_Th_Pr_Oth!$C$5:$C$111,"Pr",COPO_Th_Pr_Oth!H$5:H$111,"1") -> 8 | H9: =SUMIFS(COPO_Th_Pr_Oth!$D$5:$D$111,COPO_Th_Pr_Oth!$C$5:$C$111,"Pr",COPO_Th_Pr_Oth!I$5:I$111,"1") -> 2 | I9: =SUM(D9:H9) -> 34
C10: Other | D10: =SUMIFS(COPO_Th_Pr_Oth!$D$5:$D$111,COPO_Th_Pr_Oth!$C$5:$C$111,"Oth",COPO_Th_Pr_Oth!E$5:E$111,"1") -> 0 | E10: =SUMIFS(COPO_Th_Pr_Oth!$D$5:$D$111,COPO_Th_Pr_Oth!$C$5:$C$111,"Oth",COPO_Th_Pr_Oth!F$5:F$111,"1") -> 0 | F10: =SUMIFS(COPO_Th_Pr_Oth!$D$5:$D$111,COPO_Th_Pr_Oth!$C$5:$C$111,"Oth",COPO_Th_Pr_Oth!G$5:G$111,"1") -> 0 | G10: =SUMIFS(COPO_Th_Pr_Oth!$D$5:$D$111,COPO_Th_Pr_Oth!$C$5:$C$111,"Oth",COPO_Th_Pr_Oth!H$5:H$111,"1") -> 0 | H10: =SUMIFS(COPO_Th_Pr_Oth!$D$5:$D$111,COPO_Th_Pr_Oth!$C$5:$C$111,"Oth",COPO_Th_Pr_Oth!I$5:I$111,"1") -> 0 | I10: =SUM(D10:H10) -> 0
C11: Total | D11: =SUM(D8:D10) -> 59 | E11: =SUM(E8:E10) -> 10 | F11: =SUM(F8:F10) -> 12 | G11: =SUM(G8:G10) -> 25 | H11: =SUM(H8:H10) -> 10 | I11: =SUM(D11:H11) -> 116
C13: Total Hours planned for CO's (Percentages)
C14: Th | D14: =(D8/$I$8)*100 -> 54.878049 | E14: =(E8/$I$8)*100 -> 7.3170732 | F14: =(F8/$I$8)*100 -> 7.3170732 | G14: =(G8/$I$8)*100 -> 20.731707 | H14: =(H8/$I$8)*100 -> 9.7560976
C15: Lab | D15: =(D9/$I$9)*100 -> 41.176471 | E15: =(E9/$I$9)*100 -> 11.764706 | F15: =(F9/$I$9)*100 -> 17.647059 | G15: =(G9/$I$9)*100 -> 23.529412 | H15: =(H9/$I$9)*100 -> 5.8823529
C16: Other | D16: =(D10/$I$10)*100 -> #DIV/0! | E16: =(E10/$I$10)*100 -> #DIV/0! | F16: =(F10/$I$10)*100 -> #DIV/0! | G16: =(G10/$I$10)*100 -> #DIV/0! | H16: =(H10/$I$10)*100 -> #DIV/0!
D17: =(D11/$I$11)*100 -> 50.862069 | E17: =(E11/$I$11)*100 -> 8.6206897 | F17: =(F11/$I$11)*100 -> 10.344828 | G17: =(G11/$I$11)*100 -> 21.551724 | H17: =(H11/$I$11)*100 -> 8.6206897
C20: Total Hours for all CO-PO/PSO combinations | S20: Total Hours For CO
D21: PO1 | E21: PO2 | F21: PO3 | G21: PO4 | H21: PO5 | I21: PO6 | J21: PO7 | K21: PO8 | L21: PO9 | M21: PO10 | N21: PO11 | O21: PSO4 | P21: PSO1 | Q21: PSO2 | R21: PSO3
C22: CO1 | D22: =COPO_Th_Pr_Oth!AA4 -> 59 | E22: =COPO_Th_Pr_Oth!AB4 -> 59 | F22: =COPO_Th_Pr_Oth!AC4 -> 58 | G22: =COPO_Th_Pr_Oth!AD4 -> 26 | H22: =COPO_Th_Pr_Oth!AE4 -> 30 | I22: =COPO_Th_Pr_Oth!AF4 -> 0 | J22: =COPO_Th_Pr_Oth!AG4 -> 0 | K22: =COPO_Th_Pr_Oth!AH4 -> 10 | ... R22: =COPO_Th_Pr_Oth!AO4 -> 16 | S22: =D$11 -> 59
C23: CO2 | D23: =COPO_Th_Pr_Oth!AQ4 -> 10 | E23: =COPO_Th_Pr_Oth!AR4 -> 10 | F23: =COPO_Th_Pr_Oth!AS4 -> 10 | G23: =COPO_Th_Pr_Oth!AT4 -> 3 | H23: =COPO_Th_Pr_Oth!AU4 -> 6 | I23: =COPO_Th_Pr_Oth!AV4 -> 0 | J23: =COPO_Th_Pr_Oth!AW4 -> 0 | K23: =COPO_Th_Pr_Oth!AX4 -> 3 | ... P23: =COPO_Th_Pr_Oth!BC4 -> 6 | Q23: =COPO_Th_Pr_Oth!AN5 -> 0 | R23: =COPO_Th_Pr_Oth!BE4 -> 5 | S23: =E$11 -> 10
C24: CO3 | D24: =COPO_Th_Pr_Oth!BG4 -> 12 | E24: =COPO_Th_Pr_Oth!BH4 -> 12 | F24: =COPO_Th_Pr_Oth!BI4 -> 12 | G24: =COPO_Th_Pr_Oth!BJ4 -> 2 | H24: =COPO_Th_Pr_Oth!BK4 -> 8 | I24: =COPO_Th_Pr_Oth!BL4 -> 0 | J24: =COPO_Th_Pr_Oth!BM4 -> 0 | K24: =COPO_Th_Pr_Oth!BN4 -> 2 | ... P24: =COPO_Th_Pr_Oth!BS4 -> 6 | Q24: =COPO_Th_Pr_Oth!AN6 -> 0 | R24: =COPO_Th_Pr_Oth!BU4 -> 0 | S24: =F$11 -> 12
C25: CO4 | D25: =COPO_Th_Pr_Oth!BW4 -> 25 | E25: =COPO_Th_Pr_Oth!BX4 -> 25 | F25: =COPO_Th_Pr_Oth!BY4 -> 25 | G25: =COPO_Th_Pr_Oth!BZ4 -> 14 | H25: =COPO_Th_Pr_Oth!CA4 -> 20 | I25: =COPO_Th_Pr_Oth!CB4 -> 0 | J25: =COPO_Th_Pr_Oth!CC4 -> 0 | K25: =COPO_Th_Pr_Oth!CD4 -> 5 | ... P25: =COPO_Th_Pr_Oth!CI4 -> 17 | Q25: =COPO_Th_Pr_Oth!AN7 -> 0 | R25: =COPO_Th_Pr_Oth!CK4 -> 7 | S25: =G$11 -> 25
C26: CO5 | D26: =COPO_Th_Pr_Oth!CM4 -> 10 | E26: =COPO_Th_Pr_Oth!CN4 -> 10 | F26: =COPO_Th_Pr_Oth!CO4 -> 10 | G26: =COPO_Th_Pr_Oth!CP4 -> 0 | H26: =COPO_Th_Pr_Oth!CQ4 -> 2 | I26: =COPO_Th_Pr_Oth!CR4 -> 0 | J26: =COPO_Th_Pr_Oth!CS4 -> 0 | K26: =COPO_Th_Pr_Oth!CT4 -> 0 | ... P26: =COPO_Th_Pr_Oth!CY4 -> 8 | Q26: =COPO_Th_Pr_Oth!AN8 -> 0 | R26: =COPO_Th_Pr_Oth!DA4 -> 0 | S26: =H$11 -> 10
D27: =SUM(D22:D26) -> 116 | E27: =SUM(E22:E26) -> 116 | F27: =SUM(F22:F26) -> 115 | G27: =SUM(G22:G26) -> 45 | H27: =SUM(H22:H26) -> 66 | I27: =SUM(I22:I26) -> 0 | J27: =SUM(J22:J26) -> 0 | K27: =SUM(K22:K26) -> 20 | ... R27: =SUM(R22:R26) -> 28 | S27: =I$11 -> 116
C30: CO-PO/PSO mapping
D31: PO1 | E31: PO2 | F31: PO3 | G31: PO4 | H31: PO5 | I31: PO6 | J31: PO7 | K31: PO8 | L31: PO9 | M31: PO10 | N31: PO11 | O31: PSO4 | P31: PSO1 | Q31: PSO2 | R31: PSO3
C32: CO1 | D32: =IF($S22>0,IF((D22/$S22*100)>50,3,IF((D22/$S22*100)>25,2,IF((D22/$S22*100)>10,1,""))),"") -> 3 | E32: =IF($S22>0,IF((E22/$S22*100)>50,3,IF((E22/$S22*100)>25,2,IF((E22/$S22*100)>10,1,""))),"") -> 3 | F32: =IF($S22>0,IF((F22/$S22*100)>50,3,IF((F22/$S22*100)>25,2,IF((F22/$S22*100)>10,1,""))),"") -> 3 | G32: =IF($S22>0,IF((G22/$S22*100)>50,3,IF((G22/$S22*100)>25,2,IF((G22/$S22*100)>10,1,""))),"") -> 2 | H32: =IF($S22>0,IF((H22/$S22*100)>50,3,IF((H22/$S22*100)>25,2,IF((H22/$S22*100)>10,1,""))),"") -> 3 | I32: =IF($S22>0,IF((I22/$S22*100)>50,3,IF((I22/$S22*100)>25,2,IF((I22/$S22*100)>10,1,""))),"") | J32: =IF($S22>0,IF((J22/$S22*100)>50,3,IF((J22/$S22*100)>25,2,IF((J22/$S22*100)>10,1,""))),"") | K32: =IF($S22>0,IF((K22/$S22*100)>50,3,IF((K22/$S22*100)>25,2,IF((K22/$S22*100)>10,1,""))),"") -> 1 | ... R32: =IF($S22>0,IF((R22/$S22*100)>50,3,IF((R22/$S22*100)>25,2,IF((R22/$S22*100)>10,1,""))),"") -> 2
C33: CO2 | D33: =IF($S23>0,IF((D23/$S23*100)>50,3,IF((D23/$S23*100)>25,2,IF((D23/$S23*100)>10,1,""))),"") -> 3 | E33: =IF($S23>0,IF((E23/$S23*100)>50,3,IF((E23/$S23*100)>25,2,IF((E23/$S23*100)>10,1,""))),"") -> 3 | F33: =IF($S23>0,IF((F23/$S23*100)>50,3,IF((F23/$S23*100)>25,2,IF((F23/$S23*100)>10,1,""))),"") -> 3 | G33: =IF($S23>0,IF((G23/$S23*100)>50,3,IF((G23/$S23*100)>25,2,IF((G23/$S23*100)>10,1,""))),"") -> 2 | H33: =IF($S23>0,IF((H23/$S23*100)>50,3,IF((H23/$S23*100)>25,2,IF((H23/$S23*100)>10,1,""))),"") -> 3 | I33: =IF($S23>0,IF((I23/$S23*100)>50,3,IF((I23/$S23*100)>25,2,IF((I23/$S23*100)>10,1,""))),"") | J33: =IF($S23>0,IF((J23/$S23*100)>50,3,IF((J23/$S23*100)>25,2,IF((J23/$S23*100)>10,1,""))),"") | K33: =IF($S23>0,IF((K23/$S23*100)>50,3,IF((K23/$S23*100)>25,2,IF((K23/$S23*100)>10,1,""))),"") -> 2 | ... R33: =IF($S23>0,IF((R23/$S23*100)>50,3,IF((R23/$S23*100)>25,2,IF((R23/$S23*100)>10,1,""))),"") -> 2
C34: CO3 | D34: =IF($S24>0,IF((D24/$S24*100)>50,3,IF((D24/$S24*100)>25,2,IF((D24/$S24*100)>10,1,""))),"") -> 3 | E34: =IF($S24>0,IF((E24/$S24*100)>50,3,IF((E24/$S24*100)>25,2,IF((E24/$S24*100)>10,1,""))),"") -> 3 | F34: =IF($S24>0,IF((F24/$S24*100)>50,3,IF((F24/$S24*100)>25,2,IF((F24/$S24*100)>10,1,""))),"") -> 3 | G34: =IF($S24>0,IF((G24/$S24*100)>50,3,IF((G24/$S24*100)>25,2,IF((G24/$S24*100)>10,1,""))),"") -> 1 | H34: =IF($S24>0,IF((H24/$S24*100)>50,3,IF((H24/$S24*100)>25,2,IF((H24/$S24*100)>10,1,""))),"") -> 3 | I34: =IF($S24>0,IF((I24/$S24*100)>50,3,IF((I24/$S24*100)>25,2,IF((I24/$S24*100)>10,1,""))),"") | J34: =IF($S24>0,IF((J24/$S24*100)>50,3,IF((J24/$S24*100)>25,2,IF((J24/$S24*100)>10,1,""))),"") | K34: =IF($S24>0,IF((K24/$S24*100)>50,3,IF((K24/$S24*100)>25,2,IF((K24/$S24*100)>10,1,""))),"") -> 1 | ... R34: =IF($S24>0,IF((R24/$S24*100)>50,3,IF((R24/$S24*100)>25,2,IF((R24/$S24*100)>10,1,""))),"")
C35: CO4 | D35: =IF($S25>0,IF((D25/$S25*100)>50,3,IF((D25/$S25*100)>25,2,IF((D25/$S25*100)>10,1,""))),"") -> 3 | E35: =IF($S25>0,IF((E25/$S25*100)>50,3,IF((E25/$S25*100)>25,2,IF((E25/$S25*100)>10,1,""))),"") -> 3 | F35: =IF($S25>0,IF((F25/$S25*100)>50,3,IF((F25/$S25*100)>25,2,IF((F25/$S25*100)>10,1,""))),"") -> 3 | G35: =IF($S25>0,IF((G25/$S25*100)>50,3,IF((G25/$S25*100)>25,2,IF((G25/$S25*100)>10,1,""))),"") -> 3 | H35: =IF($S25>0,IF((H25/$S25*100)>50,3,IF((H25/$S25*100)>25,2,IF((H25/$S25*100)>10,1,""))),"") -> 3 | I35: =IF($S25>0,IF((I25/$S25*100)>50,3,IF((I25/$S25*100)>25,2,IF((I25/$S25*100)>10,1,""))),"") | J35: =IF($S25>0,IF((J25/$S25*100)>50,3,IF((J25/$S25*100)>25,2,IF((J25/$S25*100)>10,1,""))),"") | K35: =IF($S25>0,IF((K25/$S25*100)>50,3,IF((K25/$S25*100)>25,2,IF((K25/$S25*100)>10,1,""))),"") -> 1 | ... R35: =IF($S25>0,IF((R25/$S25*100)>50,3,IF((R25/$S25*100)>25,2,IF((R25/$S25*100)>10,1,""))),"") -> 2
C36: CO5 | D36: =IF($S26>0,IF((D26/$S26*100)>50,3,IF((D26/$S26*100)>25,2,IF((D26/$S26*100)>10,1,""))),"") -> 3 | E36: =IF($S26>0,IF((E26/$S26*100)>50,3,IF((E26/$S26*100)>25,2,IF((E26/$S26*100)>10,1,""))),"") -> 3 | F36: =IF($S26>0,IF((F26/$S26*100)>50,3,IF((F26/$S26*100)>25,2,IF((F26/$S26*100)>10,1,""))),"") -> 3 | G36: =IF($S26>0,IF((G26/$S26*100)>50,3,IF((G26/$S26*100)>25,2,IF((G26/$S26*100)>10,1,""))),"") | H36: =IF($S26>0,IF((H26/$S26*100)>50,3,IF((H26/$S26*100)>25,2,IF((H26/$S26*100)>10,1,""))),"") -> 1 | I36: =IF($S26>0,IF((I26/$S26*100)>50,3,IF((I26/$S26*100)>25,2,IF((I26/$S26*100)>10,1,""))),"") | J36: =IF($S26>0,IF((J26/$S26*100)>50,3,IF((J26/$S26*100)>25,2,IF((J26/$S26*100)>10,1,""))),"") | K36: =IF($S26>0,IF((K26/$S26*100)>50,3,IF((K26/$S26*100)>25,2,IF((K26/$S26*100)>10,1,""))),"") | ... R36: =IF($S26>0,IF((R26/$S26*100)>50,3,IF((R26/$S26*100)>25,2,IF((R26/$S26*100)>10,1,""))),"")
C37: Avg. | D37: =IFERROR(AVERAGE(D32:D36),"") -> 3 | E37: =IFERROR(AVERAGE(E32:E36),"") -> 3 | F37: =IFERROR(AVERAGE(F32:F36),"") -> 3 | G37: =IFERROR(AVERAGE(G32:G36),"") -> 2 | H37: =IFERROR(AVERAGE(H32:H36),"") -> 2.6 | I37: =IFERROR(AVERAGE(I32:I36),"") | J37: =IFERROR(AVERAGE(J32:J36),"") | K37: =IFERROR(AVERAGE(K32:K36),"") -> 1.25 | ... R37: =IFERROR(AVERAGE(R32:R36),"") -> 2

Sheet COPO_Th_Pr_Oth
A1: Unit/ Sub-unit | B1: Topic | C1: Load Type | D1: Hrs. | E1: COs | J1: POs | V1: PSOs | AA1: CO1-POs (Hours) | AM1: PSOs | AQ1: CO2-POs (Hours) | BC1: PSOs | BG1: CO3-POs (Hours) | BS1: PSOs | BW1: CO4-POs (Hours) | CI1: PSOs | CM1: CO5-POs (Hours) | CY1: PSOs
E2: CO1 | F2: CO2 | G2: CO3 | H2: CO4 | I2: CO5 | J2: Engineering Knowledge | K2: Problem Analysis | L2: Des/Dev of Sol | M2: Inv Cmplx Prob | N2: Tool usage | O2: Engineer and The World | P2: Ethics | Q2: Individual And Collaborative Team Work | R2: Communication | S2: Project Management and Finance | T2: Life-Long Learning | U2: PSO4 | V2: PSO1 | W2: PSO2 | X2: PSO3 | AA2: Compu Know. | AB2: Prob Ana | AC2: Des/Dev of Sol | AD2: Inv Cmplx Prob | AE2: Tool usage | AF2: Ethics | AG2: Life-long learning | AH2: Proj mgmt & fin | AI2: Communication | AJ2: Er. And soc. Concern | AK2: Ind & Team work | AL2: PSO4 | AM2: PSO1 | AN2: PSO2 | AO2: PSO3 | AQ2: Compu Know. | AR2: Prob Ana | AS2: Des/Dev of Sol | AT2: Inv Cmplx Prob | AU2: Tool usage | AV2: Ethics | AW2: Life-long learning | AX2: Proj mgmt & fin | AY2: Communication | AZ2: Er. And soc. Concern | BA2: Ind & Team work | BB2: PSO4 | BC2: PSO1 | BD2: PSO2 | BE2: PSO3 | BG2: Compu Know. | BH2: Prob Ana | BI2: Des/Dev of Sol | BJ2: Inv Cmplx Prob | BK2: Tool usage | BL2: Ethics | BM2: Life-long learning | BN2: Proj mgmt & fin | BO2: Communication | BP2: Er. And soc. Concern | BQ2: Ind & Team work | BR2: PSO4 | BS2: PSO1 | BT2: PSO2 | BU2: PSO3 | BW2: Compu Know. | BX2: Prob Ana | BY2: Des/Dev of Sol | BZ2: Inv Cmplx Prob | CA2: Tool usage | CB2: Ethics | CC2: Life-long learning | CD2: Proj mgmt & fin | CE2: Communication | CF2: Er. And soc. Concern | CG2: Ind & Team work | CH2: PSO4 | CI2: PSO1 | CJ2: PSO2 | CK2: PSO3 | CM2: Compu Know. | CN2: Prob Ana | CO2: Des/Dev of Sol | CP2: Inv Cmplx Prob | CQ2: Tool usage | CR2: Ethics | CS2: Life-long learning | CT2: Proj mgmt & fin | CU2: Communication | CV2: Er. And soc. Concern | CW2: Ind & Team work | CX2: PSO4 | CY2: PSO1 | CZ2: PSO2 | DA2: PSO3
E3: 1 | F3: 2 | G3: 3 | H3: 4 | I3: 5 | J3: 1 | K3: 2 | L3: 3 | M3: 4 | N3: 5 | O3: 6 | P3: 7 | Q3: 8 | R3: 9 | S3: 10 | T3: 11 | U3: 12 | V3: 1 | W3: 2 | X3: 3 | Y3: 4 | AA3: 1 | AB3: 2 | AC3: 3 | AD3: 4 | AE3: 5 | AF3: 6 | AG3: 7 | AH3: 8 | AI3: 9 | AJ3: 10 | AK3: 11 | AL3: 12 | AM3: 1 | AN3: 2 | AO3: 3 | AQ3: 1 | AR3: 2 | AS3: 3 | AT3: 4 | AU3: 5 | AV3: 6 | AW3: 7 | AX3: 8 | AY3: 9 | AZ3: 10 | BA3: 11 | BB3: 12 | BC3: 1 | BD3: 2 | BE3: 3 | BG3: 1 | BH3: 2 | BI3: 3 | BJ3: 4 | BK3: 5 | BL3: 6 | BM3: 7 | BN3: 8 | BO3: 9 | BP3: 10 | BQ3: 11 | BR3: 12 | BS3: 1 | BT3: 2 | BU3: 3 | BW3: 1 | BX3: 2 | BY3: 3 | BZ3: 4 | CA3: 5 | CB3: 6 | CC3: 7 | CD3: 8 | CE3: 9 | CF3: 10 | CG3: 11 | CH3: 12 | CI3: 1 | CJ3: 2 | CK3: 3 | CM3: 1 | CN3: 2 | CO3: 3 | CP3: 4 | CQ3: 5 | CR3: 6 | CS3: 7 | CT3: 8 | CU3: 9 | CV3: 10 | CW3: 11 | CX3: 12 | CY3: 1 | CZ3: 2 | DA3: 3
E4: =COUNTA(E5:E111) -> 51 | F4: =COUNTA(F5:F111) -> 8 | G4: =COUNTA(G5:G111) -> 9 | H4: =COUNTA(H5:H111) -> 21 | I4: =COUNTA(I5:I111) -> 9 | J4: =COUNTA(J5:J111) -> 54 | K4: =COUNTA(K5:K111) -> 54 | L4: =COUNTA(L5:L111) -> 53 | ... Y4: =COUNTA(Y5:Y111) -> 0 | AA4: =SUM(AA5:AA111) -> 59 | AB4: =SUM(AB5:AB111) -> 59 | AC4: =SUM(AC5:AC111) -> 58 | AD4: =SUM(AD5:AD111) -> 26 | AE4: =SUM(AE5:AE111) -> 30 | AF4: =SUM(AF5:AF111) -> 0 | AG4: =SUM(AG5:AG111) -> 0 | AH4: =SUM(AH5:AH111) -> 10 | ... AO4: =SUM(AO5:AO111) -> 16 | AQ4: =SUM(AQ5:AQ111) -> 10 | AR4: =SUM(AR5:AR111) -> 10 | AS4: =SUM(AS5:AS111) -> 10 | AT4: =SUM(AT5:AT111) -> 3 | AU4: =SUM(AU5:AU111) -> 6 | AV4: =SUM(AV5:AV111) -> 0 | AW4: =SUM(AW5:AW111) -> 0 | AX4: =SUM(AX5:AX111) -> 3 | ... BE4: =SUM(BE5:BE111) -> 5 | BG4: =SUM(BG5:BG111) -> 12 | BH4: =SUM(BH5:BH111) -> 12 | BI4: =SUM(BI5:BI111) -> 12 | BJ4: =SUM(BJ5:BJ111) -> 2 | BK4: =SUM(BK5:BK111) -> 8 | BL4: =SUM(BL5:BL111) -> 0 | BM4: =SUM(BM5:BM111) -> 0 | BN4: =SUM(BN5:BN111) -> 2 | ... BU4: =SUM(BU5:BU111) -> 0 | BW4: =SUM(BW5:BW111) -> 25 | BX4: =SUM(BX5:BX111) -> 25 | BY4: =SUM(BY5:BY111) -> 25 | BZ4: =SUM(BZ5:BZ111) -> 14 | CA4: =SUM(CA5:CA111) -> 20 | CB4: =SUM(CB5:CB111) -> 0 | CC4: =SUM(CC5:CC111) -> 0 | CD4: =SUM(CD5:CD111) -> 5 | ... CK4: =SUM(CK5:CK111) -> 7 | CM4: =SUM(CM5:CM111) -> 10 | CN4: =SUM(CN5:CN111) -> 10 | CO4: =SUM(CO5:CO111) -> 10 | CP4: =SUM(CP5:CP111) -> 0 | CQ4: =SUM(CQ5:CQ111) -> 2 | CR4: =SUM(CR5:CR111) -> 0 | CS4: =SUM(CS5:CS111) -> 0 | CT4: =SUM(CT5:CT111) -> 0 | ... DA4: =SUM(DA5:DA111) -> 0
A5: Unit 1 | B5: Differential, multi-stage and operational amplifiers | AA5: =$D5*$E5*J5 -> 0 | AB5: =$D5*$E5*K5 -> 0 | AC5: =$D5*$E5*L5 -> 0 | AD5: =$D5*$E5*M5 -> 0 | AE5: =$D5*$E5*N5 -> 0 | AF5: =$D5*$E5*O5 -> 0 | AG5: =$D5*$E5*P5 -> 0 | AH5: =$D5*$E5*Q5 -> 0 | ... AO5: =$D5*$E5*X5 -> 0 | AQ5: =$D5*$F5*J5 -> 0 | AR5: =$D5*$F5*K5 -> 0 | AS5: =$D5*$F5*L5 -> 0 | AT5: =$D5*$F5*M5 -> 0 | AU5: =$D5*$F5*N5 -> 0 | AV5: =$D5*$F5*O5 -> 0 | AW5: =$D5*$F5*P5 -> 0 | AX5: =$D5*$F5*Q5 -> 0 | ... BE5: =$D5*$F5*X5 -> 0 | BG5: =$D5*$G5*J5 -> 0 | BH5: =$D5*$G5*K5 -> 0 | BI5: =$D5*$G5*L5 -> 0 | BJ5: =$D5*$G5*M5 -> 0 | BK5: =$D5*$G5*N5 -> 0 | BL5: =$D5*$G5*O5 -> 0 | BM5: =$D5*$G5*P5 -> 0 | BN5: =$D5*$G5*Q5 -> 0 | ... BU5: =$D5*$G5*X5 -> 0 | BW5: =$D5*$H5*J5 -> 0 | BX5: =$D5*$H5*K5 -> 0 | BY5: =$D5*$H5*L5 -> 0 | BZ5: =$D5*$H5*M5 -> 0 | CA5: =$D5*$H5*N5 -> 0 | CB5: =$D5*$H5*O5 -> 0 | CC5: =$D5*$H5*P5 -> 0 | CD5: =$D5*$H5*Q5 -> 0 | ... CK5: =$D5*$H5*X5 -> 0 | CM5: =$D5*$I5*J5 -> 0 | CN5: =$D5*$I5*K5 -> 0 | CO5: =$D5*$I5*L5 -> 0 | CP5: =$D5*$I5*M5 -> 0 | CQ5: =$D5*$I5*N5 -> 0 | CR5: =$D5*$I5*O5 -> 0 | CS5: =$D5*$I5*P5 -> 0 | CT5: =$D5*$I5*Q5 -> 0 | ... DA5: =$D5*$I5*X5 -> 0
A6: 1.1 | B6: Differential Amplifier | C6: Th | D6: 2 | E6: 1 | J6: 1 | K6: 1 | L6: 1 | M6: 1 | S6: 1 | V6: 1 | X6: 1 | AA6: =$D6*$E6*J6 -> 2 | AB6: =$D6*$E6*K6 -> 2 | AC6: =$D6*$E6*L6 -> 2 | AD6: =$D6*$E6*M6 -> 2 | AE6: =$D6*$E6*N6 -> 0 | AF6: =$D6*$E6*O6 -> 0 | AG6: =$D6*$E6*P6 -> 0 | AH6: =$D6*$E6*Q6 -> 0 | ... AO6: =$D6*$E6*X6 -> 2 | AQ6: =$D6*$F6*J6 -> 0 | AR6: =$D6*$F6*K6 -> 0 | AS6: =$D6*$F6*L6 -> 0 | AT6: =$D6*$F6*M6 -> 0 | AU6: =$D6*$F6*N6 -> 0 | AV6: =$D6*$F6*O6 -> 0 | AW6: =$D6*$F6*P6 -> 0 | AX6: =$D6*$F6*Q6 -> 0 | ... BE6: =$D6*$F6*X6 -> 0 | BG6: =$D6*$G6*J6 -> 0 | BH6: =$D6*$G6*K6 -> 0 | BI6: =$D6*$G6*L6 -> 0 | BJ6: =$D6*$G6*M6 -> 0 | BK6: =$D6*$G6*N6 -> 0 | BL6: =$D6*$G6*O6 -> 0 | BM6: =$D6*$G6*P6 -> 0 | BN6: =$D6*$G6*Q6 -> 0 | ... BU6: =$D6*$G6*X6 -> 0 | BW6: =$D6*$H6*J6 -> 0 | BX6: =$D6*$H6*K6 -> 0 | BY6: =$D6*$H6*L6 -> 0 | BZ6: =$D6*$H6*M6 -> 0 | CA6: =$D6*$H6*N6 -> 0 | CB6: =$D6*$H6*O6 -> 0 | CC6: =$D6*$H6*P6 -> 0 | CD6: =$D6*$H6*Q6 -> 0 | ... CK6: =$D6*$H6*X6 -> 0 | CM6: =$D6*$I6*J6 -> 0 | CN6: =$D6*$I6*K6 -> 0 | CO6: =$D6*$I6*L6 -> 0 | CP6: =$D6*$I6*M6 -> 0 | CQ6: =$D6*$I6*N6 -> 0 | CR6: =$D6*$I6*O6 -> 0 | CS6: =$D6*$I6*P6 -> 0 | CT6: =$D6*$I6*Q6 -> 0 | ... DA6: =$D6*$I6*X6 -> 0
A7: 1.2 | B7: Power Amplifier | C7: Th | D7: 1 | E7: 1 | J7: 1 | K7: 1 | L7: 1 | M7: 1 | S7: 1 | V7: 1 | X7: 1 | AA7: =$D7*$E7*J7 -> 1 | AB7: =$D7*$E7*K7 -> 1 | AC7: =$D7*$E7*L7 -> 1 | AD7: =$D7*$E7*M7 -> 1 | AE7: =$D7*$E7*N7 -> 0 | AF7: =$D7*$E7*O7 -> 0 | AG7: =$D7*$E7*P7 -> 0 | AH7: =$D7*$E7*Q7 -> 0 | ... AO7: =$D7*$E7*X7 -> 1 | AQ7: =$D7*$F7*J7 -> 0 | AR7: =$D7*$F7*K7 -> 0 | AS7: =$D7*$F7*L7 -> 0 | AT7: =$D7*$F7*M7 -> 0 | AU7: =$D7*$F7*N7 -> 0 | AV7: =$D7*$F7*O7 -> 0 | AW7: =$D7*$F7*P7 -> 0 | AX7: =$D7*$F7*Q7 -> 0 | ... BE7: =$D7*$F7*X7 -> 0 | BG7: =$D7*$G7*J7 -> 0 | BH7: =$D7*$G7*K7 -> 0 | BI7: =$D7*$G7*L7 -> 0 | BJ7: =$D7*$G7*M7 -> 0 | BK7: =$D7*$G7*N7 -> 0 | BL7: =$D7*$G7*O7 -> 0 | BM7: =$D7*$G7*P7 -> 0 | BN7: =$D7*$G7*Q7 -> 0 | ... BU7: =$D7*$G7*X7 -> 0 | BW7: =$D7*$H7*J7 -> 0 | BX7: =$D7*$H7*K7 -> 0 | BY7: =$D7*$H7*L7 -> 0 | BZ7: =$D7*$H7*M7 -> 0 | CA7: =$D7*$H7*N7 -> 0 | CB7: =$D7*$H7*O7 -> 0 | CC7: =$D7*$H7*P7 -> 0 | CD7: =$D7*$H7*Q7 -> 0 | ... CK7: =$D7*$H7*X7 -> 0 | CM7: =$D7*$I7*J7 -> 0 | CN7: =$D7*$I7*K7 -> 0 | CO7: =$D7*$I7*L7 -> 0 | CP7: =$D7*$I7*M7 -> 0 | CQ7: =$D7*$I7*N7 -> 0 | CR7: =$D7*$I7*O7 -> 0 | CS7: =$D7*$I7*P7 -> 0 | CT7: =$D7*$I7*Q7 -> 0 | ... DA7: =$D7*$I7*X7 -> 0
A8: 1.3 | B8: Direct Coupled Multi-Stage Amplifier | C8: Th | D8: 1 | E8: 1 | J8: 1 | K8: 1 | L8: 1 | M8: 1 | S8: 1 | V8: 1 | X8: 1 | AA8: =$D8*$E8*J8 -> 1 | AB8: =$D8*$E8*K8 -> 1 | AC8: =$D8*$E8*L8 -> 1 | AD8: =$D8*$E8*M8 -> 1 | AE8: =$D8*$E8*N8 -> 0 | AF8: =$D8*$E8*O8 -> 0 | AG8: =$D8*$E8*P8 -> 0 | AH8: =$D8*$E8*Q8 -> 0 | ... AO8: =$D8*$E8*X8 -> 1 | AQ8: =$D8*$F8*J8 -> 0 | AR8: =$D8*$F8*K8 -> 0 | AS8: =$D8*$F8*L8 -> 0 | AT8: =$D8*$F8*M8 -> 0 | AU8: =$D8*$F8*N8 -> 0 | AV8: =$D8*$F8*O8 -> 0 | AW8: =$D8*$F8*P8 -> 0 | AX8: =$D8*$F8*Q8 -> 0 | ... BE8: =$D8*$F8*X8 -> 0 | BG8: =$D8*$G8*J8 -> 0 | BH8: =$D8*$G8*K8 -> 0 | BI8: =$D8*$G8*L8 -> 0 | BJ8: =$D8*$G8*M8 -> 0 | BK8: =$D8*$G8*N8 -> 0 | BL8: =$D8*$G8*O8 -> 0 | BM8: =$D8*$G8*P8 -> 0 | BN8: =$D8*$G8*Q8 -> 0 | ... BU8: =$D8*$G8*X8 -> 0 | BW8: =$D8*$H8*J8 -> 0 | BX8: =$D8*$H8*K8 -> 0 | BY8: =$D8*$H8*L8 -> 0 | BZ8: =$D8*$H8*M8 -> 0 | CA8: =$D8*$H8*N8 -> 0 | CB8: =$D8*$H8*O8 -> 0 | CC8: =$D8*$H8*P8 -> 0 | CD8: =$D8*$H8*Q8 -> 0 | ... CK8: =$D8*$H8*X8 -> 0 | CM8: =$D8*$I8*J8 -> 0 | CN8: =$D8*$I8*K8 -> 0 | CO8: =$D8*$I8*L8 -> 0 | CP8: =$D8*$I8*M8 -> 0 | CQ8: =$D8*$I8*N8 -> 0 | CR8: =$D8*$I8*O8 -> 0 | CS8: =$D8*$I8*P8 -> 0 | CT8: =$D8*$I8*Q8 -> 0 | ... DA8: =$D8*$I8*X8 -> 0
A9: 1.4 | B9: Internal Structure of an Operational Amplifier | C9: Th | D9: 1 | E9: 1 | J9: 1 | K9: 1 | V9: 1 | AA9: =$D9*$E9*J9 -> 1 | AB9: =$D9*$E9*K9 -> 1 | AC9: =$D9*$E9*L9 -> 0 | AD9: =$D9*$E9*M9 -> 0 | AE9: =$D9*$E9*N9 -> 0 | AF9: =$D9*$E9*O9 -> 0 | AG9: =$D9*$E9*P9 -> 0 | AH9: =$D9*$E9*Q9 -> 0 | ... AO9: =$D9*$E9*X9 -> 0 | AQ9: =$D9*$F9*J9 -> 0 | AR9: =$D9*$F9*K9 -> 0 | AS9: =$D9*$F9*L9 -> 0 | AT9: =$D9*$F9*M9 -> 0 | AU9: =$D9*$F9*N9 -> 0 | AV9: =$D9*$F9*O9 -> 0 | AW9: =$D9*$F9*P9 -> 0 | AX9: =$D9*$F9*Q9 -> 0 | ... BE9: =$D9*$F9*X9 -> 0 | BG9: =$D9*$G9*J9 -> 0 | BH9: =$D9*$G9*K9 -> 0 | BI9: =$D9*$G9*L9 -> 0 | BJ9: =$D9*$G9*M9 -> 0 | BK9: =$D9*$G9*N9 -> 0 | BL9: =$D9*$G9*O9 -> 0 | BM9: =$D9*$G9*P9 -> 0 | BN9: =$D9*$G9*Q9 -> 0 | ... BU9: =$D9*$G9*X9 -> 0 | BW9: =$D9*$H9*J9 -> 0 | BX9: =$D9*$H9*K9 -> 0 | BY9: =$D9*$H9*L9 -> 0 | BZ9: =$D9*$H9*M9 -> 0 | CA9: =$D9*$H9*N9 -> 0 | CB9: =$D9*$H9*O9 -> 0 | CC9: =$D9*$H9*P9 -> 0 | CD9: =$D9*$H9*Q9 -> 0 | ... CK9: =$D9*$H9*X9 -> 0 | CM9: =$D9*$I9*J9 -> 0 | CN9: =$D9*$I9*K9 -> 0 | CO9: =$D9*$I9*L9 -> 0 | CP9: =$D9*$I9*M9 -> 0 | CQ9: =$D9*$I9*N9 -> 0 | CR9: =$D9*$I9*O9 -> 0 | CS9: =$D9*$I9*P9 -> 0 | CT9: =$D9*$I9*Q9 -> 0 | ... DA9: =$D9*$I9*X9 -> 0
A10: 1.5 | B10: Ideal Op-Amp, Non-Idealities in an Op-Amp | C10: Th | D10: 1 | E10: 1 | J10: 1 | K10: 1 | L10: 1 | M10: 1 | S10: 1 | V10: 1 | AA10: =$D10*$E10*J10 -> 1 | AB10: =$D10*$E10*K10 -> 1 | AC10: =$D10*$E10*L10 -> 1 | AD10: =$D10*$E10*M10 -> 1 | AE10: =$D10*$E10*N10 -> 0 | AF10: =$D10*$E10*O10 -> 0 | AG10: =$D10*$E10*P10 -> 0 | AH10: =$D10*$E10*Q10 -> 0 | ... AO10: =$D10*$E10*X10 -> 0 | AQ10: =$D10*$F10*J10 -> 0 | AR10: =$D10*$F10*K10 -> 0 | AS10: =$D10*$F10*L10 -> 0 | AT10: =$D10*$F10*M10 -> 0 | AU10: =$D10*$F10*N10 -> 0 | AV10: =$D10*$F10*O10 -> 0 | AW10: =$D10*$F10*P10 -> 0 | AX10: =$D10*$F10*Q10 -> 0 | ... BE10: =$D10*$F10*X10 -> 0 | BG10: =$D10*$G10*J10 -> 0 | BH10: =$D10*$G10*K10 -> 0 | BI10: =$D10*$G10*L10 -> 0 | BJ10: =$D10*$G10*M10 -> 0 | BK10: =$D10*$G10*N10 -> 0 | BL10: =$D10*$G10*O10 -> 0 | BM10: =$D10*$G10*P10 -> 0 | BN10: =$D10*$G10*Q10 -> 0 | ... BU10: =$D10*$G10*X10 -> 0 | BW10: =$D10*$H10*J10 -> 0 | BX10: =$D10*$H10*K10 -> 0 | BY10: =$D10*$H10*L10 -> 0 | BZ10: =$D10*$H10*M10 -> 0 | CA10: =$D10*$H10*N10 -> 0 | CB10: =$D10*$H10*O10 -> 0 | CC10: =$D10*$H10*P10 -> 0 | CD10: =$D10*$H10*Q10 -> 0 | ... CK10: =$D10*$H10*X10 -> 0 | CM10: =$D10*$I10*J10 -> 0 | CN10: =$D10*$I10*K10 -> 0 | CO10: =$D10*$I10*L10 -> 0 | CP10: =$D10*$I10*M10 -> 0 | CQ10: =$D10*$I10*N10 -> 0 | CR10: =$D10*$I10*O10 -> 0 | CS10: =$D10*$I10*P10 -> 0 | CT10: =$D10*$I10*Q10 -> 0 | ... DA10: =$D10*$I10*X10 -> 0
A11: 1.6 | B11: Output Offset Voltage, Input Bias Current | C11: Th | D11: 1 | E11: 1 | J11: 1 | K11: 1 | L11: 1 | M11: 1 | V11: 1 | W11: 1 | AA11: =$D11*$E11*J11 -> 1 | AB11: =$D11*$E11*K11 -> 1 | AC11: =$D11*$E11*L11 -> 1 | AD11: =$D11*$E11*M11 -> 1 | AE11: =$D11*$E11*N11 -> 0 | AF11: =$D11*$E11*O11 -> 0 | AG11: =$D11*$E11*P11 -> 0 | AH11: =$D11*$E11*Q11 -> 0 | ... AO11: =$D11*$E11*X11 -> 0 | AQ11: =$D11*$F11*J11 -> 0 | AR11: =$D11*$F11*K11 -> 0 | AS11: =$D11*$F11*L11 -> 0 | AT11: =$D11*$F11*M11 -> 0 | AU11: =$D11*$F11*N11 -> 0 | AV11: =$D11*$F11*O11 -> 0 | AW11: =$D11*$F11*P11 -> 0 | AX11: =$D11*$F11*Q11 -> 0 | ... BE11: =$D11*$F11*X11 -> 0 | BG11: =$D11*$G11*J11 -> 0 | BH11: =$D11*$G11*K11 -> 0 | BI11: =$D11*$G11*L11 -> 0 | BJ11: =$D11*$G11*M11 -> 0 | BK11: =$D11*$G11*N11 -> 0 | BL11: =$D11*$G11*O11 -> 0 | BM11: =$D11*$G11*P11 -> 0 | BN11: =$D11*$G11*Q11 -> 0 | ... BU11: =$D11*$G11*X11 -> 0 | BW11: =$D11*$H11*J11 -> 0 | BX11: =$D11*$H11*K11 -> 0 | BY11: =$D11*$H11*L11 -> 0 | BZ11: =$D11*$H11*M11 -> 0 | CA11: =$D11*$H11*N11 -> 0 | CB11: =$D11*$H11*O11 -> 0 | CC11: =$D11*$H11*P11 -> 0 | CD11: =$D11*$H11*Q11 -> 0 | ... CK11: =$D11*$H11*X11 -> 0 | CM11: =$D11*$I11*J11 -> 0 | CN11: =$D11*$I11*K11 -> 0 | CO11: =$D11*$I11*L11 -> 0 | CP11: =$D11*$I11*M11 -> 0 | CQ11: =$D11*$I11*N11 -> 0 | CR11: =$D11*$I11*O11 -> 0 | CS11: =$D11*$I11*P11 -> 0 | CT11: =$D11*$I11*Q11 -> 0 | ... DA11: =$D11*$I11*X11 -> 0
A12: 1.7 | B12: Input Offset Current, Slew Rate, Gain Bandwidth Product | C12: Th | D12: 1 | E12: 1 | J12: 1 | K12: 1 | L12: 1 | M12: 1 | S12: 1 | V12: 1 | W12: 1 | AA12: =$D12*$E12*J12 -> 1 | AB12: =$D12*$E12*K12 -> 1 | AC12: =$D12*$E12*L12 -> 1 | AD12: =$D12*$E12*M12 -> 1 | AE12: =$D12*$E12*N12 -> 0 | AF12: =$D12*$E12*O12 -> 0 | AG12: =$D12*$E12*P12 -> 0 | AH12: =$D12*$E12*Q12 -> 0 | ... AO12: =$D12*$E12*X12 -> 0 | AQ12: =$D12*$F12*J12 -> 0 | AR12: =$D12*$F12*K12 -> 0 | AS12: =$D12*$F12*L12 -> 0 | AT12: =$D12*$F12*M12 -> 0 | AU12: =$D12*$F12*N12 -> 0 | AV12: =$D12*$F12*O12 -> 0 | AW12: =$D12*$F12*P12 -> 0 | AX12: =$D12*$F12*Q12 -> 0 | ... BE12: =$D12*$F12*X12 -> 0 | BG12: =$D12*$G12*J12 -> 0 | BH12: =$D12*$G12*K12 -> 0 | BI12: =$D12*$G12*L12 -> 0 | BJ12: =$D12*$G12*M12 -> 0 | BK12: =$D12*$G12*N12 -> 0 | BL12: =$D12*$G12*O12 -> 0 | BM12: =$D12*$G12*P12 -> 0 | BN12: =$D12*$G12*Q12 -> 0 | ... BU12: =$D12*$G12*X12 -> 0 | BW12: =$D12*$H12*J12 -> 0 | BX12: =$D12*$H12*K12 -> 0 | BY12: =$D12*$H12*L12 -> 0 | BZ12: =$D12*$H12*M12 -> 0 | CA12: =$D12*$H12*N12 -> 0 | CB12: =$D12*$H12*O12 -> 0 | CC12: =$D12*$H12*P12 -> 0 | CD12: =$D12*$H12*Q12 -> 0 | ... CK12: =$D12*$H12*X12 -> 0 | CM12: =$D12*$I12*J12 -> 0 | CN12: =$D12*$I12*K12 -> 0 | CO12: =$D12*$I12*L12 -> 0 | CP12: =$D12*$I12*M12 -> 0 | CQ12: =$D12*$I12*N12 -> 0 | CR12: =$D12*$I12*O12 -> 0 | CS12: =$D12*$I12*P12 -> 0 | CT12: =$D12*$I12*Q12 -> 0 | ... DA12: =$D12*$I12*X12 -> 0
A13: Unit 2 | B13: Linear applications of op-amp | AA13: =$D13*$E13*J13 -> 0 | AB13: =$D13*$E13*K13 -> 0 | AC13: =$D13*$E13*L13 -> 0 | AD13: =$D13*$E13*M13 -> 0 | AE13: =$D13*$E13*N13 -> 0 | AF13: =$D13*$E13*O13 -> 0 | AG13: =$D13*$E13*P13 -> 0 | AH13: =$D13*$E13*Q13 -> 0 | ... AO13: =$D13*$E13*X13 -> 0 | AQ13: =$D13*$F13*J13 -> 0 | AR13: =$D13*$F13*K13 -> 0 | AS13: =$D13*$F13*L13 -> 0 | AT13: =$D13*$F13*M13 -> 0 | AU13: =$D13*$F13*N13 -> 0 | AV13: =$D13*$F13*O13 -> 0 | AW13: =$D13*$F13*P13 -> 0 | AX13: =$D13*$F13*Q13 -> 0 | ... BE13: =$D13*$F13*X13 -> 0 | BG13: =$D13*$G13*J13 -> 0 | BH13: =$D13*$G13*K13 -> 0 | BI13: =$D13*$G13*L13 -> 0 | BJ13: =$D13*$G13*M13 -> 0 | BK13: =$D13*$G13*N13 -> 0 | BL13: =$D13*$G13*O13 -> 0 | BM13: =$D13*$G13*P13 -> 0 | BN13: =$D13*$G13*Q13 -> 0 | ... BU13: =$D13*$G13*X13 -> 0 | BW13: =$D13*$H13*J13 -> 0 | BX13: =$D13*$H13*K13 -> 0 | BY13: =$D13*$H13*L13 -> 0 | BZ13: =$D13*$H13*M13 -> 0 | CA13: =$D13*$H13*N13 -> 0 | CB13: =$D13*$H13*O13 -> 0 | CC13: =$D13*$H13*P13 -> 0 | CD13: =$D13*$H13*Q13 -> 0 | ... CK13: =$D13*$H13*X13 -> 0 | CM13: =$D13*$I13*J13 -> 0 | CN13: =$D13*$I13*K13 -> 0 | CO13: =$D13*$I13*L13 -> 0 | CP13: =$D13*$I13*M13 -> 0 | CQ13: =$D13*$I13*N13 -> 0 | CR13: =$D13*$I13*O13 -> 0 | CS13: =$D13*$I13*P13 -> 0 | CT13: =$D13*$I13*Q13 -> 0 | ... DA13: =$D13*$I13*X13 -> 0
A14: 2.1 | B14: Idealized Analysis of Op-Amp Circuits | C14: Th | D14: 1 | E14: 1 | F14: 1 | J14: 1 | K14: 1 | L14: 1 | M14: 1 | U14: 1 | V14: 1 | W14: 1 | AA14: =$D14*$E14*J14 -> 1 | AB14: =$D14*$E14*K14 -> 1 | AC14: =$D14*$E14*L14 -> 1 | AD14: =$D14*$E14*M14 -> 1 | AE14: =$D14*$E14*N14 -> 0 | AF14: =$D14*$E14*O14 -> 0 | AG14: =$D14*$E14*P14 -> 0 | AH14: =$D14*$E14*Q14 -> 0 | ... AO14: =$D14*$E14*X14 -> 0 | AQ14: =$D14*$F14*J14 -> 1 | AR14: =$D14*$F14*K14 -> 1 | AS14: =$D14*$F14*L14 -> 1 | AT14: =$D14*$F14*M14 -> 1 | AU14: =$D14*$F14*N14 -> 0 | AV14: =$D14*$F14*O14 -> 0 | AW14: =$D14*$F14*P14 -> 0 | AX14: =$D14*$F14*Q14 -> 0 | ... BE14: =$D14*$F14*X14 -> 0 | BG14: =$D14*$G14*J14 -> 0 | BH14: =$D14*$G14*K14 -> 0 | BI14: =$D14*$G14*L14 -> 0 | BJ14: =$D14*$G14*M14 -> 0 | BK14: =$D14*$G14*N14 -> 0 | BL14: =$D14*$G14*O14 -> 0 | BM14: =$D14*$G14*P14 -> 0 | BN14: =$D14*$G14*Q14 -> 0 | ... BU14: =$D14*$G14*X14 -> 0 | BW14: =$D14*$H14*J14 -> 0 | BX14: =$D14*$H14*K14 -> 0 | BY14: =$D14*$H14*L14 -> 0 | BZ14: =$D14*$H14*M14 -> 0 | CA14: =$D14*$H14*N14 -> 0 | CB14: =$D14*$H14*O14 -> 0 | CC14: =$D14*$H14*P14 -> 0 | CD14: =$D14*$H14*Q14 -> 0 | ... CK14: =$D14*$H14*X14 -> 0 | CM14: =$D14*$I14*J14 -> 0 | CN14: =$D14*$I14*K14 -> 0 | CO14: =$D14*$I14*L14 -> 0 | CP14: =$D14*$I14*M14 -> 0 | CQ14: =$D14*$I14*N14 -> 0 | CR14: =$D14*$I14*O14 -> 0 | CS14: =$D14*$I14*P14 -> 0 | CT14: =$D14*$I14*Q14 -> 0 | ... DA14: =$D14*$I14*X14 -> 0
A15: 2.2 | B15: Inverting and Non-Inverting Amplifier | C15: Th | D15: 1 | E15: 1 | F15: 1 | J15: 1 | K15: 1 | L15: 1 | U15: 1 | V15: 1 | W15: 1 | X15: 1 | AA15: =$D15*$E15*J15 -> 1 | AB15: =$D15*$E15*K15 -> 1 | AC15: =$D15*$E15*L15 -> 1 | AD15: =$D15*$E15*M15 -> 0 | AE15: =$D15*$E15*N15 -> 0 | AF15: =$D15*$E15*O15 -> 0 | AG15: =$D15*$E15*P15 -> 0 | AH15: =$D15*$E15*Q15 -> 0 | ... AO15: =$D15*$E15*X15 -> 1 | AQ15: =$D15*$F15*J15 -> 1 | AR15: =$D15*$F15*K15 -> 1 | AS15: =$D15*$F15*L15 -> 1 | AT15: =$D15*$F15*M15 -> 0 | AU15: =$D15*$F15*N15 -> 0 | AV15: =$D15*$F15*O15 -> 0 | AW15: =$D15*$F15*P15 -> 0 | AX15: =$D15*$F15*Q15 -> 0 | ... BE15: =$D15*$F15*X15 -> 1 | BG15: =$D15*$G15*J15 -> 0 | BH15: =$D15*$G15*K15 -> 0 | BI15: =$D15*$G15*L15 -> 0 | BJ15: =$D15*$G15*M15 -> 0 | BK15: =$D15*$G15*N15 -> 0 | BL15: =$D15*$G15*O15 -> 0 | BM15: =$D15*$G15*P15 -> 0 | BN15: =$D15*$G15*Q15 -> 0 | ... BU15: =$D15*$G15*X15 -> 0 | BW15: =$D15*$H15*J15 -> 0 | BX15: =$D15*$H15*K15 -> 0 | BY15: =$D15*$H15*L15 -> 0 | BZ15: =$D15*$H15*M15 -> 0 | CA15: =$D15*$H15*N15 -> 0 | CB15: =$D15*$H15*O15 -> 0 | CC15: =$D15*$H15*P15 -> 0 | CD15: =$D15*$H15*Q15 -> 0 | ... CK15: =$D15*$H15*X15 -> 0 | CM15: =$D15*$I15*J15 -> 0 | CN15: =$D15*$I15*K15 -> 0 | CO15: =$D15*$I15*L15 -> 0 | CP15: =$D15*$I15*M15 -> 0 | CQ15: =$D15*$I15*N15 -> 0 | CR15: =$D15*$I15*O15 -> 0 | CS15: =$D15*$I15*P15 -> 0 | CT15: =$D15*$I15*Q15 -> 0 | ... DA15: =$D15*$I15*X15 -> 0
A16: 2.3 | B16: Differential Amplifier, Instrumentation Amplifier | C16: Th | D16: 1 | E16: 1 | F16: 1 | J16: 1 | K16: 1 | L16: 1 | Q16: 1 | U16: 1 | V16: 1 | W16: 1 | X16: 1 | AA16: =$D16*$E16*J16 -> 1 | AB16: =$D16*$E16*K16 -> 1 | AC16: =$D16*$E16*L16 -> 1 | AD16: =$D16*$E16*M16 -> 0 | AE16: =$D16*$E16*N16 -> 0 | AF16: =$D16*$E16*O16 -> 0 | AG16: =$D16*$E16*P16 -> 0 | AH16: =$D16*$E16*Q16 -> 1 | ... AO16: =$D16*$E16*X16 -> 1 | AQ16: =$D16*$F16*J16 -> 1 | AR16: =$D16*$F16*K16 -> 1 | AS16: =$D16*$F16*L16 -> 1 | AT16: =$D16*$F16*M16 -> 0 | AU16: =$D16*$F16*N16 -> 0 | AV16: =$D16*$F16*O16 -> 0 | AW16: =$D16*$F16*P16 -> 0 | AX16: =$D16*$F16*Q16 -> 1 | ... BE16: =$D16*$F16*X16 -> 1 | BG16: =$D16*$G16*J16 -> 0 | BH16: =$D16*$G16*K16 -> 0 | BI16: =$D16*$G16*L16 -> 0 | BJ16: =$D16*$G16*M16 -> 0 | BK16: =$D16*$G16*N16 -> 0 | BL16: =$D16*$G16*O16 -> 0 | BM16: =$D16*$G16*P16 -> 0 | BN16: =$D16*$G16*Q16 -> 0 | ... BU16: =$D16*$G16*X16 -> 0 | BW16: =$D16*$H16*J16 -> 0 | BX16: =$D16*$H16*K16 -> 0 | BY16: =$D16*$H16*L16 -> 0 | BZ16: =$D16*$H16*M16 -> 0 | CA16: =$D16*$H16*N16 -> 0 | CB16: =$D16*$H16*O16 -> 0 | CC16: =$D16*$H16*P16 -> 0 | CD16: =$D16*$H16*Q16 -> 0 | ... CK16: =$D16*$H16*X16 -> 0 | CM16: =$D16*$I16*J16 -> 0 | CN16: =$D16*$I16*K16 -> 0 | CO16: =$D16*$I16*L16 -> 0 | CP16: =$D16*$I16*M16 -> 0 | CQ16: =$D16*$I16*N16 -> 0 | CR16: =$D16*$I16*O16 -> 0 | CS16: =$D16*$I16*P16 -> 0 | CT16: =$D16*$I16*Q16 -> 0 | ... DA16: =$D16*$I16*X16 -> 0
A17: 2.4 | B17: Integrator and Differentiator | C17: Th | D17: 1 | E17: 1 | F17: 1 | J17: 1 | K17: 1 | L17: 1 | V17: 1 | W17: 1 | X17: 1 | AA17: =$D17*$E17*J17 -> 1 | AB17: =$D17*$E17*K17 -> 1 | AC17: =$D17*$E17*L17 -> 1 | AD17: =$D17*$E17*M17 -> 0 | AE17: =$D17*$E17*N17 -> 0 | AF17: =$D17*$E17*O17 -> 0 | AG17: =$D17*$E17*P17 -> 0 | AH17: =$D17*$E17*Q17 -> 0 | ... AO17: =$D17*$E17*X17 -> 1 | AQ17: =$D17*$F17*J17 -> 1 | AR17: =$D17*$F17*K17 -> 1 | AS17: =$D17*$F17*L17 -> 1 | AT17: =$D17*$F17*M17 -> 0 | AU17: =$D17*$F17*N17 -> 0 | AV17: =$D17*$F17*O17 -> 0 | AW17: =$D17*$F17*P17 -> 0 | AX17: =$D17*$F17*Q17 -> 0 | ... BE17: =$D17*$F17*X17 -> 1 | BG17: =$D17*$G17*J17 -> 0 | BH17: =$D17*$G17*K17 -> 0 | BI17: =$D17*$G17*L17 -> 0 | BJ17: =$D17*$G17*M17 -> 0 | BK17: =$D17*$G17*N17 -> 0 | BL17: =$D17*$G17*O17 -> 0 | BM17: =$D17*$G17*P17 -> 0 | BN17: =$D17*$G17*Q17 -> 0 | ... BU17: =$D17*$G17*X17 -> 0 | BW17: =$D17*$H17*J17 -> 0 | BX17: =$D17*$H17*K17 -> 0 | BY17: =$D17*$H17*L17 -> 0 | BZ17: =$D17*$H17*M17 -> 0 | CA17: =$D17*$H17*N17 -> 0 | CB17: =$D17*$H17*O17 -> 0 | CC17: =$D17*$H17*P17 -> 0 | CD17: =$D17*$H17*Q17 -> 0 | ... CK17: =$D17*$H17*X17 -> 0 | CM17: =$D17*$I17*J17 -> 0 | CN17: =$D17*$I17*K17 -> 0 | CO17: =$D17*$I17*L17 -> 0 | CP17: =$D17*$I17*M17 -> 0 | CQ17: =$D17*$I17*N17 -> 0 | CR17: =$D17*$I17*O17 -> 0 | CS17: =$D17*$I17*P17 -> 0 | CT17: =$D17*$I17*Q17 -> 0 | ... DA17: =$D17*$I17*X17 -> 0
A18: 2.5 | B18: Active Filter, Voltage regulator | C18: Th | D18: 1 | E18: 1 | F18: 1 | J18: 1 | K18: 1 | L18: 1 | M18: 1 | N18: 1 | Q18: 1 | S18: 1 | V18: 1 | W18: 1 | X18: 1 | AA18: =$D18*$E18*J18 -> 1 | AB18: =$D18*$E18*K18 -> 1 | AC18: =$D18*$E18*L18 -> 1 | AD18: =$D18*$E18*M18 -> 1 | AE18: =$D18*$E18*N18 -> 1 | AF18: =$D18*$E18*O18 -> 0 | AG18: =$D18*$E18*P18 -> 0 | AH18: =$D18*$E18*Q18 -> 1 | ... AO18: =$D18*$E18*X18 -> 1 | AQ18: =$D18*$F18*J18 -> 1 | AR18: =$D18*$F18*K18 -> 1 | AS18: =$D18*$F18*L18 -> 1 | AT18: =$D18*$F18*M18 -> 1 | AU18: =$D18*$F18*N18 -> 1 | AV18: =$D18*$F18*O18 -> 0 | AW18: =$D18*$F18*P18 -> 0 | AX18: =$D18*$F18*Q18 -> 1 | ... BE18: =$D18*$F18*X18 -> 1 | BG18: =$D18*$G18*J18 -> 0 | BH18: =$D18*$G18*K18 -> 0 | BI18: =$D18*$G18*L18 -> 0 | BJ18: =$D18*$G18*M18 -> 0 | BK18: =$D18*$G18*N18 -> 0 | BL18: =$D18*$G18*O18 -> 0 | BM18: =$D18*$G18*P18 -> 0 | BN18: =$D18*$G18*Q18 -> 0 | ... BU18: =$D18*$G18*X18 -> 0 | BW18: =$D18*$H18*J18 -> 0 | BX18: =$D18*$H18*K18 -> 0 | BY18: =$D18*$H18*L18 -> 0 | BZ18: =$D18*$H18*M18 -> 0 | CA18: =$D18*$H18*N18 -> 0 | CB18: =$D18*$H18*O18 -> 0 | CC18: =$D18*$H18*P18 -> 0 | CD18: =$D18*$H18*Q18 -> 0 | ... CK18: =$D18*$H18*X18 -> 0 | CM18: =$D18*$I18*J18 -> 0 | CN18: =$D18*$I18*K18 -> 0 | CO18: =$D18*$I18*L18 -> 0 | CP18: =$D18*$I18*M18 -> 0 | CQ18: =$D18*$I18*N18 -> 0 | CR18: =$D18*$I18*O18 -> 0 | CS18: =$D18*$I18*P18 -> 0 | CT18: =$D18*$I18*Q18 -> 0 | ... DA18: =$D18*$I18*X18 -> 0
A19: 2.6 | B19: Oscillators (Wein Bridge and Phase Shift) | C19: Th | D19: 1 | E19: 1 | F19: 1 | J19: 1 | K19: 1 | L19: 1 | M19: 1 | N19: 1 | Q19: 1 | S19: 1 | V19: 1 | W19: 1 | X19: 1 | AA19: =$D19*$E19*J19 -> 1 | AB19: =$D19*$E19*K19 -> 1 | AC19: =$D19*$E19*L19 -> 1 | AD19: =$D19*$E19*M19 -> 1 | AE19: =$D19*$E19*N19 -> 1 | AF19: =$D19*$E19*O19 -> 0 | AG19: =$D19*$E19*P19 -> 0 | AH19: =$D19*$E19*Q19 -> 1 | ... AO19: =$D19*$E19*X19 -> 1 | AQ19: =$D19*$F19*J19 -> 1 | AR19: =$D19*$F19*K19 -> 1 | AS19: =$D19*$F19*L19 -> 1 | AT19: =$D19*$F19*M19 -> 1 | AU19: =$D19*$F19*N19 -> 1 | AV19: =$D19*$F19*O19 -> 0 | AW19: =$D19*$F19*P19 -> 0 | AX19: =$D19*$F19*Q19 -> 1 | ... BE19: =$D19*$F19*X19 -> 1 | BG19: =$D19*$G19*J19 -> 0 | BH19: =$D19*$G19*K19 -> 0 | BI19: =$D19*$G19*L19 -> 0 | BJ19: =$D19*$G19*M19 -> 0 | BK19: =$D19*$G19*N19 -> 0 | BL19: =$D19*$G19*O19 -> 0 | BM19: =$D19*$G19*P19 -> 0 | BN19: =$D19*$G19*Q19 -> 0 | ... BU19: =$D19*$G19*X19 -> 0 | BW19: =$D19*$H19*J19 -> 0 | BX19: =$D19*$H19*K19 -> 0 | BY19: =$D19*$H19*L19 -> 0 | BZ19: =$D19*$H19*M19 -> 0 | CA19: =$D19*$H19*N19 -> 0 | CB19: =$D19*$H19*O19 -> 0 | CC19: =$D19*$H19*P19 -> 0 | CD19: =$D19*$H19*Q19 -> 0 | ... CK19: =$D19*$H19*X19 -> 0 | CM19: =$D19*$I19*J19 -> 0 | CN19: =$D19*$I19*K19 -> 0 | CO19: =$D19*$I19*L19 -> 0 | CP19: =$D19*$I19*M19 -> 0 | CQ19: =$D19*$I19*N19 -> 0 | CR19: =$D19*$I19*O19 -> 0 | CS19: =$D19*$I19*P19 -> 0 | CT19: =$D19*$I19*Q19 -> 0 | ... DA19: =$D19*$I19*X19 -> 0
A20: Unit 3 | B20: Nonlinear applications of op-amp | AA20: =$D20*$E20*J20 -> 0 | AB20: =$D20*$E20*K20 -> 0 | AC20: =$D20*$E20*L20 -> 0 | AD20: =$D20*$E20*M20 -> 0 | AE20: =$D20*$E20*N20 -> 0 | AF20: =$D20*$E20*O20 -> 0 | AG20: =$D20*$E20*P20 -> 0 | AH20: =$D20*$E20*Q20 -> 0 | ... AO20: =$D20*$E20*X20 -> 0 | AQ20: =$D20*$F20*J20 -> 0 | AR20: =$D20*$F20*K20 -> 0 | AS20: =$D20*$F20*L20 -> 0 | AT20: =$D20*$F20*M20 -> 0 | AU20: =$D20*$F20*N20 -> 0 | AV20: =$D20*$F20*O20 -> 0 | AW20: =$D20*$F20*P20 -> 0 | AX20: =$D20*$F20*Q20 -> 0 | ... BE20: =$D20*$F20*X20 -> 0 | BG20: =$D20*$G20*J20 -> 0 | BH20: =$D20*$G20*K20 -> 0 | BI20: =$D20*$G20*L20 -> 0 | BJ20: =$D20*$G20*M20 -> 0 | BK20: =$D20*$G20*N20 -> 0 | BL20: =$D20*$G20*O20 -> 0 | BM20: =$D20*$G20*P20 -> 0 | BN20: =$D20*$G20*Q20 -> 0 | ... BU20: =$D20*$G20*X20 -> 0 | BW20: =$D20*$H20*J20 -> 0 | BX20: =$D20*$H20*K20 -> 0 | BY20: =$D20*$H20*L20 -> 0 | BZ20: =$D20*$H20*M20 -> 0 | CA20: =$D20*$H20*N20 -> 0 | CB20: =$D20*$H20*O20 -> 0 | CC20: =$D20*$H20*P20 -> 0 | CD20: =$D20*$H20*Q20 -> 0 | ... CK20: =$D20*$H20*X20 -> 0 | CM20: =$D20*$I20*J20 -> 0 | CN20: =$D20*$I20*K20 -> 0 | CO20: =$D20*$I20*L20 -> 0 | CP20: =$D20*$I20*M20 -> 0 | CQ20: =$D20*$I20*N20 -> 0 | CR20: =$D20*$I20*O20 -> 0 | CS20: =$D20*$I20*P20 -> 0 | CT20: =$D20*$I20*Q20 -> 0 | ... DA20: =$D20*$I20*X20 -> 0
A21: 3.1 | B21: Hysteretic Comparator | C21: Th | D21: 1 | E21: 1 | G21: 1 | J21: 1 | K21: 1 | L21: 1 | S21: 1 | V21: 1 | W21: 1 | AA21: =$D21*$E21*J21 -> 1 | AB21: =$D21*$E21*K21 -> 1 | AC21: =$D21*$E21*L21 -> 1 | AD21: =$D21*$E21*M21 -> 0 | AE21: =$D21*$E21*N21 -> 0 | AF21: =$D21*$E21*O21 -> 0 | AG21: =$D21*$E21*P21 -> 0 | AH21: =$D21*$E21*Q21 -> 0 | ... AO21: =$D21*$E21*X21 -> 0 | AQ21: =$D21*$F21*J21 -> 0 | AR21: =$D21*$F21*K21 -> 0 | AS21: =$D21*$F21*L21 -> 0 | AT21: =$D21*$F21*M21 -> 0 | AU21: =$D21*$F21*N21 -> 0 | AV21: =$D21*$F21*O21 -> 0 | AW21: =$D21*$F21*P21 -> 0 | AX21: =$D21*$F21*Q21 -> 0 | ... BE21: =$D21*$F21*X21 -> 0 | BG21: =$D21*$G21*J21 -> 1 | BH21: =$D21*$G21*K21 -> 1 | BI21: =$D21*$G21*L21 -> 1 | BJ21: =$D21*$G21*M21 -> 0 | BK21: =$D21*$G21*N21 -> 0 | BL21: =$D21*$G21*O21 -> 0 | BM21: =$D21*$G21*P21 -> 0 | BN21: =$D21*$G21*Q21 -> 0 | ... BU21: =$D21*$G21*X21 -> 0 | BW21: =$D21*$H21*J21 -> 0 | BX21: =$D21*$H21*K21 -> 0 | BY21: =$D21*$H21*L21 -> 0 | BZ21: =$D21*$H21*M21 -> 0 | CA21: =$D21*$H21*N21 -> 0 | CB21: =$D21*$H21*O21 -> 0 | CC21: =$D21*$H21*P21 -> 0 | CD21: =$D21*$H21*Q21 -> 0 | ... CK21: =$D21*$H21*X21 -> 0 | CM21: =$D21*$I21*J21 -> 0 | CN21: =$D21*$I21*K21 -> 0 | CO21: =$D21*$I21*L21 -> 0 | CP21: =$D21*$I21*M21 -> 0 | CQ21: =$D21*$I21*N21 -> 0 | CR21: =$D21*$I21*O21 -> 0 | CS21: =$D21*$I21*P21 -> 0 | CT21: =$D21*$I21*Q21 -> 0 | ... DA21: =$D21*$I21*X21 -> 0
A22: 3.2 | B22: Zero Crossing Detector | C22: Th | D22: 1 | E22: 1 | G22: 1 | J22: 1 | K22: 1 | L22: 1 | V22: 1 | W22: 1 | AA22: =$D22*$E22*J22 -> 1 | AB22: =$D22*$E22*K22 -> 1 | AC22: =$D22*$E22*L22 -> 1 | AD22: =$D22*$E22*M22 -> 0 | AE22: =$D22*$E22*N22 -> 0 | AF22: =$D22*$E22*O22 -> 0 | AG22: =$D22*$E22*P22 -> 0 | AH22: =$D22*$E22*Q22 -> 0 | ... AO22: =$D22*$E22*X22 -> 0 | AQ22: =$D22*$F22*J22 -> 0 | AR22: =$D22*$F22*K22 -> 0 | AS22: =$D22*$F22*L22 -> 0 | AT22: =$D22*$F22*M22 -> 0 | AU22: =$D22*$F22*N22 -> 0 | AV22: =$D22*$F22*O22 -> 0 | AW22: =$D22*$F22*P22 -> 0 | AX22: =$D22*$F22*Q22 -> 0 | ... BE22: =$D22*$F22*X22 -> 0 | BG22: =$D22*$G22*J22 -> 1 | BH22: =$D22*$G22*K22 -> 1 | BI22: =$D22*$G22*L22 -> 1 | BJ22: =$D22*$G22*M22 -> 0 | BK22: =$D22*$G22*N22 -> 0 | BL22: =$D22*$G22*O22 -> 0 | BM22: =$D22*$G22*P22 -> 0 | BN22: =$D22*$G22*Q22 -> 0 | ... BU22: =$D22*$G22*X22 -> 0 | BW22: =$D22*$H22*J22 -> 0 | BX22: =$D22*$H22*K22 -> 0 | BY22: =$D22*$H22*L22 -> 0 | BZ22: =$D22*$H22*M22 -> 0 | CA22: =$D22*$H22*N22 -> 0 | CB22: =$D22*$H22*O22 -> 0 | CC22: =$D22*$H22*P22 -> 0 | CD22: =$D22*$H22*Q22 -> 0 | ... CK22: =$D22*$H22*X22 -> 0 | CM22: =$D22*$I22*J22 -> 0 | CN22: =$D22*$I22*K22 -> 0 | CO22: =$D22*$I22*L22 -> 0 | CP22: =$D22*$I22*M22 -> 0 | CQ22: =$D22*$I22*N22 -> 0 | CR22: =$D22*$I22*O22 -> 0 | CS22: =$D22*$I22*P22 -> 0 | CT22: =$D22*$I22*Q22 -> 0 | ... DA22: =$D22*$I22*X22 -> 0
A23: 3.3 | B23: Square-wave generators | C23: Th | D23: 1 | E23: 1 | G23: 1 | J23: 1 | K23: 1 | L23: 1 | M23: 1 | N23: 1 | Q23: 1 | S23: 1 | T23: 1 | U23: 1 | V23: 1 | W23: 1 | AA23: =$D23*$E23*J23 -> 1 | AB23: =$D23*$E23*K23 -> 1 | AC23: =$D23*$E23*L23 -> 1 | AD23: =$D23*$E23*M23 -> 1 | AE23: =$D23*$E23*N23 -> 1 | AF23: =$D23*$E23*O23 -> 0 | AG23: =$D23*$E23*P23 -> 0 | AH23: =$D23*$E23*Q23 -> 1 | ... AO23: =$D23*$E23*X23 -> 0 | AQ23: =$D23*$F23*J23 -> 0 | AR23: =$D23*$F23*K23 -> 0 | AS23: =$D23*$F23*L23 -> 0 | AT23: =$D23*$F23*M23 -> 0 | AU23: =$D23*$F23*N23 -> 0 | AV23: =$D23*$F23*O23 -> 0 | AW23: =$D23*$F23*P23 -> 0 | AX23: =$D23*$F23*Q23 -> 0 | ... BE23: =$D23*$F23*X23 -> 0 | BG23: =$D23*$G23*J23 -> 1 | BH23: =$D23*$G23*K23 -> 1 | BI23: =$D23*$G23*L23 -> 1 | BJ23: =$D23*$G23*M23 -> 1 | BK23: =$D23*$G23*N23 -> 1 | BL23: =$D23*$G23*O23 -> 0 | BM23: =$D23*$G23*P23 -> 0 | BN23: =$D23*$G23*Q23 -> 1 | ... BU23: =$D23*$G23*X23 -> 0 | BW23: =$D23*$H23*J23 -> 0 | BX23: =$D23*$H23*K23 -> 0 | BY23: =$D23*$H23*L23 -> 0 | BZ23: =$D23*$H23*M23 -> 0 | CA23: =$D23*$H23*N23 -> 0 | CB23: =$D23*$H23*O23 -> 0 | CC23: =$D23*$H23*P23 -> 0 | CD23: =$D23*$H23*Q23 -> 0 | ... CK23: =$D23*$H23*X23 -> 0 | CM23: =$D23*$I23*J23 -> 0 | CN23: =$D23*$I23*K23 -> 0 | CO23: =$D23*$I23*L23 -> 0 | CP23: =$D23*$I23*M23 -> 0 | CQ23: =$D23*$I23*N23 -> 0 | CR23: =$D23*$I23*O23 -> 0 | CS23: =$D23*$I23*P23 -> 0 | CT23: =$D23*$I23*Q23 -> 0 | ... DA23: =$D23*$I23*X23 -> 0
A24: 3.4 | B24: Triangular-wave generators | C24: Th | D24: 1 | E24: 1 | G24: 1 | J24: 1 | K24: 1 | L24: 1 | M24: 1 | N24: 1 | Q24: 1 | S24: 1 | T24: 1 | V24: 1 | W24: 1 | AA24: =$D24*$E24*J24 -> 1 | AB24: =$D24*$E24*K24 -> 1 | AC24: =$D24*$E24*L24 -> 1 | AD24: =$D24*$E24*M24 -> 1 | AE24: =$D24*$E24*N24 -> 1 | AF24: =$D24*$E24*O24 -> 0 | AG24: =$D24*$E24*P24 -> 0 | AH24: =$D24*$E24*Q24 -> 1 | ... AO24: =$D24*$E24*X24 -> 0 | AQ24: =$D24*$F24*J24 -> 0 | AR24: =$D24*$F24*K24 -> 0 | AS24: =$D24*$F24*L24 -> 0 | AT24: =$D24*$F24*M24 -> 0 | AU24: =$D24*$F24*N24 -> 0 | AV24: =$D24*$F24*O24 -> 0 | AW24: =$D24*$F24*P24 -> 0 | AX24: =$D24*$F24*Q24 -> 0 | ... BE24: =$D24*$F24*X24 -> 0 | BG24: =$D24*$G24*J24 -> 1 | BH24: =$D24*$G24*K24 -> 1 | BI24: =$D24*$G24*L24 -> 1 | BJ24: =$D24*$G24*M24 -> 1 | BK24: =$D24*$G24*N24 -> 1 | BL24: =$D24*$G24*O24 -> 0 | BM24: =$D24*$G24*P24 -> 0 | BN24: =$D24*$G24*Q24 -> 1 | ... BU24: =$D24*$G24*X24 -> 0 | BW24: =$D24*$H24*J24 -> 0 | BX24: =$D24*$H24*K24 -> 0 | BY24: =$D24*$H24*L24 -> 0 | BZ24: =$D24*$H24*M24 -> 0 | CA24: =$D24*$H24*N24 -> 0 | CB24: =$D24*$H24*O24 -> 0 | CC24: =$D24*$H24*P24 -> 0 | CD24: =$D24*$H24*Q24 -> 0 | ... CK24: =$D24*$H24*X24 -> 0 | CM24: =$D24*$I24*J24 -> 0 | CN24: =$D24*$I24*K24 -> 0 | CO24: =$D24*$I24*L24 -> 0 | CP24: =$D24*$I24*M24 -> 0 | CQ24: =$D24*$I24*N24 -> 0 | CR24: =$D24*$I24*O24 -> 0 | CS24: =$D24*$I24*P24 -> 0 | CT24: =$D24*$I24*Q24 -> 0 | ... DA24: =$D24*$I24*X24 -> 0
A25: 3.5 | B25: Precision rectifier | C25: Th | D25: 1 | E25: 1 | G25: 1 | J25: 1 | K25: 1 | L25: 1 | V25: 1 | W25: 1 | AA25: =$D25*$E25*J25 -> 1 | AB25: =$D25*$E25*K25 -> 1 | AC25: =$D25*$E25*L25 -> 1 | AD25: =$D25*$E25*M25 -> 0 | AE25: =$D25*$E25*N25 -> 0 | AF25: =$D25*$E25*O25 -> 0 | AG25: =$D25*$E25*P25 -> 0 | AH25: =$D25*$E25*Q25 -> 0 | ... AO25: =$D25*$E25*X25 -> 0 | AQ25: =$D25*$F25*J25 -> 0 | AR25: =$D25*$F25*K25 -> 0 | AS25: =$D25*$F25*L25 -> 0 | AT25: =$D25*$F25*M25 -> 0 | AU25: =$D25*$F25*N25 -> 0 | AV25: =$D25*$F25*O25 -> 0 | AW25: =$D25*$F25*P25 -> 0 | AX25: =$D25*$F25*Q25 -> 0 | ... BE25: =$D25*$F25*X25 -> 0 | BG25: =$D25*$G25*J25 -> 1 | BH25: =$D25*$G25*K25 -> 1 | BI25: =$D25*$G25*L25 -> 1 | BJ25: =$D25*$G25*M25 -> 0 | BK25: =$D25*$G25*N25 -> 0 | BL25: =$D25*$G25*O25 -> 0 | BM25: =$D25*$G25*P25 -> 0 | BN25: =$D25*$G25*Q25 -> 0 | ... BU25: =$D25*$G25*X25 -> 0 | BW25: =$D25*$H25*J25 -> 0 | BX25: =$D25*$H25*K25 -> 0 | BY25: =$D25*$H25*L25 -> 0 | BZ25: =$D25*$H25*M25 -> 0 | CA25: =$D25*$H25*N25 -> 0 | CB25: =$D25*$H25*O25 -> 0 | CC25: =$D25*$H25*P25 -> 0 | CD25: =$D25*$H25*Q25 -> 0 | ... CK25: =$D25*$H25*X25 -> 0 | CM25: =$D25*$I25*J25 -> 0 | CN25: =$D25*$I25*K25 -> 0 | CO25: =$D25*$I25*L25 -> 0 | CP25: =$D25*$I25*M25 -> 0 | CQ25: =$D25*$I25*N25 -> 0 | CR25: =$D25*$I25*O25 -> 0 | CS25: =$D25*$I25*P25 -> 0 | CT25: =$D25*$I25*Q25 -> 0 | ... DA25: =$D25*$I25*X25 -> 0
A26: 3.6 | B26: Peak detector | C26: Th | D26: 1 | E26: 1 | G26: 1 | J26: 1 | K26: 1 | L26: 1 | V26: 1 | W26: 1 | AA26: =$D26*$E26*J26 -> 1 | AB26: =$D26*$E26*K26 -> 1 | AC26: =$D26*$E26*L26 -> 1 | AD26: =$D26*$E26*M26 -> 0 | AE26: =$D26*$E26*N26 -> 0 | AF26: =$D26*$E26*O26 -> 0 | AG26: =$D26*$E26*P26 -> 0 | AH26: =$D26*$E26*Q26 -> 0 | ... AO26: =$D26*$E26*X26 -> 0 | AQ26: =$D26*$F26*J26 -> 0 | AR26: =$D26*$F26*K26 -> 0 | AS26: =$D26*$F26*L26 -> 0 | AT26: =$D26*$F26*M26 -> 0 | AU26: =$D26*$F26*N26 -> 0 | AV26: =$D26*$F26*O26 -> 0 | AW26: =$D26*$F26*P26 -> 0 | AX26: =$D26*$F26*Q26 -> 0 | ... BE26: =$D26*$F26*X26 -> 0 | BG26: =$D26*$G26*J26 -> 1 | BH26: =$D26*$G26*K26 -> 1 | BI26: =$D26*$G26*L26 -> 1 | BJ26: =$D26*$G26*M26 -> 0 | BK26: =$D26*$G26*N26 -> 0 | BL26: =$D26*$G26*O26 -> 0 | BM26: =$D26*$G26*P26 -> 0 | BN26: =$D26*$G26*Q26 -> 0 | ... BU26: =$D26*$G26*X26 -> 0 | BW26: =$D26*$H26*J26 -> 0 | BX26: =$D26*$H26*K26 -> 0 | BY26: =$D26*$H26*L26 -> 0 | BZ26: =$D26*$H26*M26 -> 0 | CA26: =$D26*$H26*N26 -> 0 | CB26: =$D26*$H26*O26 -> 0 | CC26: =$D26*$H26*P26 -> 0 | CD26: =$D26*$H26*Q26 -> 0 | ... CK26: =$D26*$H26*X26 -> 0 | CM26: =$D26*$I26*J26 -> 0 | CN26: =$D26*$I26*K26 -> 0 | CO26: =$D26*$I26*L26 -> 0 | CP26: =$D26*$I26*M26 -> 0 | CQ26: =$D26*$I26*N26 -> 0 | CR26: =$D26*$I26*O26 -> 0 | CS26: =$D26*$I26*P26 -> 0 | CT26: =$D26*$I26*Q26 -> 0 | ... DA26: =$D26*$I26*X26 -> 0
A27: Unit 4 | B27: Combinational Digital Circuits | AA27: =$D27*$E27*J27 -> 0 | AB27: =$D27*$E27*K27 -> 0 | AC27: =$D27*$E27*L27 -> 0 | AD27: =$D27*$E27*M27 -> 0 | AE27: =$D27*$E27*N27 -> 0 | AF27: =$D27*$E27*O27 -> 0 | AG27: =$D27*$E27*P27 -> 0 | AH27: =$D27*$E27*Q27 -> 0 | ... AO27: =$D27*$E27*X27 -> 0 | AQ27: =$D27*$F27*J27 -> 0 | AR27: =$D27*$F27*K27 -> 0 | AS27: =$D27*$F27*L27 -> 0 | AT27: =$D27*$F27*M27 -> 0 | AU27: =$D27*$F27*N27 -> 0 | AV27: =$D27*$F27*O27 -> 0 | AW27: =$D27*$F27*P27 -> 0 | AX27: =$D27*$F27*Q27 -> 0 | ... BE27: =$D27*$F27*X27 -> 0 | BG27: =$D27*$G27*J27 -> 0 | BH27: =$D27*$G27*K27 -> 0 | BI27: =$D27*$G27*L27 -> 0 | BJ27: =$D27*$G27*M27 -> 0 | BK27: =$D27*$G27*N27 -> 0 | BL27: =$D27*$G27*O27 -> 0 | BM27: =$D27*$G27*P27 -> 0 | BN27: =$D27*$G27*Q27 -> 0 | ... BU27: =$D27*$G27*X27 -> 0 | BW27: =$D27*$H27*J27 -> 0 | BX27: =$D27*$H27*K27 -> 0 | BY27: =$D27*$H27*L27 -> 0 | BZ27: =$D27*$H27*M27 -> 0 | CA27: =$D27*$H27*N27 -> 0 | CB27: =$D27*$H27*O27 -> 0 | CC27: =$D27*$H27*P27 -> 0 | CD27: =$D27*$H27*Q27 -> 0 | ... CK27: =$D27*$H27*X27 -> 0 | CM27: =$D27*$I27*J27 -> 0 | CN27: =$D27*$I27*K27 -> 0 | CO27: =$D27*$I27*L27 -> 0 | CP27: =$D27*$I27*M27 -> 0 | CQ27: =$D27*$I27*N27 -> 0 | CR27: =$D27*$I27*O27 -> 0 | CS27: =$D27*$I27*P27 -> 0 | CT27: =$D27*$I27*Q27 -> 0 | ... DA27: =$D27*$I27*X27 -> 0
A28: 4.1 | B28: Standard Representation for Logic Functions | C28: Th | D28: 1 | E28: 1 | H28: 1 | J28: 1 | K28: 1 | L28: 1 | U28: 1 | V28: 1 | AA28: =$D28*$E28*J28 -> 1 | AB28: =$D28*$E28*K28 -> 1 | AC28: =$D28*$E28*L28 -> 1 | AD28: =$D28*$E28*M28 -> 0 | AE28: =$D28*$E28*N28 -> 0 | AF28: =$D28*$E28*O28 -> 0 | AG28: =$D28*$E28*P28 -> 0 | AH28: =$D28*$E28*Q28 -> 0 | ... AO28: =$D28*$E28*X28 -> 0 | AQ28: =$D28*$F28*J28 -> 0 | AR28: =$D28*$F28*K28 -> 0 | AS28: =$D28*$F28*L28 -> 0 | AT28: =$D28*$F28*M28 -> 0 | AU28: =$D28*$F28*N28 -> 0 | AV28: =$D28*$F28*O28 -> 0 | AW28: =$D28*$F28*P28 -> 0 | AX28: =$D28*$F28*Q28 -> 0 | ... BE28: =$D28*$F28*X28 -> 0 | BG28: =$D28*$G28*J28 -> 0 | BH28: =$D28*$G28*K28 -> 0 | BI28: =$D28*$G28*L28 -> 0 | BJ28: =$D28*$G28*M28 -> 0 | BK28: =$D28*$G28*N28 -> 0 | BL28: =$D28*$G28*O28 -> 0 | BM28: =$D28*$G28*P28 -> 0 | BN28: =$D28*$G28*Q28 -> 0 | ... BU28: =$D28*$G28*X28 -> 0 | BW28: =$D28*$H28*J28 -> 1 | BX28: =$D28*$H28*K28 -> 1 | BY28: =$D28*$H28*L28 -> 1 | BZ28: =$D28*$H28*M28 -> 0 | CA28: =$D28*$H28*N28 -> 0 | CB28: =$D28*$H28*O28 -> 0 | CC28: =$D28*$H28*P28 -> 0 | CD28: =$D28*$H28*Q28 -> 0 | ... CK28: =$D28*$H28*X28 -> 0 | CM28: =$D28*$I28*J28 -> 0 | CN28: =$D28*$I28*K28 -> 0 | CO28: =$D28*$I28*L28 -> 0 | CP28: =$D28*$I28*M28 -> 0 | CQ28: =$D28*$I28*N28 -> 0 | CR28: =$D28*$I28*O28 -> 0 | CS28: =$D28*$I28*P28 -> 0 | CT28: =$D28*$I28*Q28 -> 0 | ... DA28: =$D28*$I28*X28 -> 0
A29: 4.2 | B29: Simplification of Logic Functions using K-map and Boolean Algebra | C29: Th | D29: 1 | E29: 1 | H29: 1 | J29: 1 | K29: 1 | L29: 1 | M29: 1 | N29: 1 | V29: 1 | W29: 1 | AA29: =$D29*$E29*J29 -> 1 | AB29: =$D29*$E29*K29 -> 1 | AC29: =$D29*$E29*L29 -> 1 | AD29: =$D29*$E29*M29 -> 1 | AE29: =$D29*$E29*N29 -> 1 | AF29: =$D29*$E29*O29 -> 0 | AG29: =$D29*$E29*P29 -> 0 | AH29: =$D29*$E29*Q29 -> 0 | ... AO29: =$D29*$E29*X29 -> 0 | AQ29: =$D29*$F29*J29 -> 0 | AR29: =$D29*$F29*K29 -> 0 | AS29: =$D29*$F29*L29 -> 0 | AT29: =$D29*$F29*M29 -> 0 | AU29: =$D29*$F29*N29 -> 0 | AV29: =$D29*$F29*O29 -> 0 | AW29: =$D29*$F29*P29 -> 0 | AX29: =$D29*$F29*Q29 -> 0 | ... BE29: =$D29*$F29*X29 -> 0 | BG29: =$D29*$G29*J29 -> 0 | BH29: =$D29*$G29*K29 -> 0 | BI29: =$D29*$G29*L29 -> 0 | BJ29: =$D29*$G29*M29 -> 0 | BK29: =$D29*$G29*N29 -> 0 | BL29: =$D29*$G29*O29 -> 0 | BM29: =$D29*$G29*P29 -> 0 | BN29: =$D29*$G29*Q29 -> 0 | ... BU29: =$D29*$G29*X29 -> 0 | BW29: =$D29*$H29*J29 -> 1 | BX29: =$D29*$H29*K29 -> 1 | BY29: =$D29*$H29*L29 -> 1 | BZ29: =$D29*$H29*M29 -> 1 | CA29: =$D29*$H29*N29 -> 1 | CB29: =$D29*$H29*O29 -> 0 | CC29: =$D29*$H29*P29 -> 0 | CD29: =$D29*$H29*Q29 -> 0 | ... CK29: =$D29*$H29*X29 -> 0 | CM29: =$D29*$I29*J29 -> 0 | CN29: =$D29*$I29*K29 -> 0 | CO29: =$D29*$I29*L29 -> 0 | CP29: =$D29*$I29*M29 -> 0 | CQ29: =$D29*$I29*N29 -> 0 | CR29: =$D29*$I29*O29 -> 0 | CS29: =$D29*$I29*P29 -> 0 | CT29: =$D29*$I29*Q29 -> 0 | ... DA29: =$D29*$I29*X29 -> 0
A30: 4.3 | B30: Don’t Care Conditions | C30: Th | D30: 1 | E30: 1 | H30: 1 | J30: 1 | K30: 1 | L30: 1 | M30: 1 | N30: 1 | V30: 1 | W30: 1 | AA30: =$D30*$E30*J30 -> 1 | AB30: =$D30*$E30*K30 -> 1 | AC30: =$D30*$E30*L30 -> 1 | AD30: =$D30*$E30*M30 -> 1 | AE30: =$D30*$E30*N30 -> 1 | AF30: =$D30*$E30*O30 -> 0 | AG30: =$D30*$E30*P30 -> 0 | AH30: =$D30*$E30*Q30 -> 0 | ... AO30: =$D30*$E30*X30 -> 0 | AQ30: =$D30*$F30*J30 -> 0 | AR30: =$D30*$F30*K30 -> 0 | AS30: =$D30*$F30*L30 -> 0 | AT30: =$D30*$F30*M30 -> 0 | AU30: =$D30*$F30*N30 -> 0 | AV30: =$D30*$F30*O30 -> 0 | AW30: =$D30*$F30*P30 -> 0 | AX30: =$D30*$F30*Q30 -> 0 | ... BE30: =$D30*$F30*X30 -> 0 | BG30: =$D30*$G30*J30 -> 0 | BH30: =$D30*$G30*K30 -> 0 | BI30: =$D30*$G30*L30 -> 0 | BJ30: =$D30*$G30*M30 -> 0 | BK30: =$D30*$G30*N30 -> 0 | BL30: =$D30*$G30*O30 -> 0 | BM30: =$D30*$G30*P30 -> 0 | BN30: =$D30*$G30*Q30 -> 0 | ... BU30: =$D30*$G30*X30 -> 0 | BW30: =$D30*$H30*J30 -> 1 | BX30: =$D30*$H30*K30 -> 1 | BY30: =$D30*$H30*L30 -> 1 | BZ30: =$D30*$H30*M30 -> 1 | CA30: =$D30*$H30*N30 -> 1 | CB30: =$D30*$H30*O30 -> 0 | CC30: =$D30*$H30*P30 -> 0 | CD30: =$D30*$H30*Q30 -> 0 | ... CK30: =$D30*$H30*X30 -> 0 | CM30: =$D30*$I30*J30 -> 0 | CN30: =$D30*$I30*K30 -> 0 | CO30: =$D30*$I30*L30 -> 0 | CP30: =$D30*$I30*M30 -> 0 | CQ30: =$D30*$I30*N30 -> 0 | CR30: =$D30*$I30*O30 -> 0 | CS30: =$D30*$I30*P30 -> 0 | CT30: =$D30*$I30*Q30 -> 0 | ... DA30: =$D30*$I30*X30 -> 0
A31: 4.4 | B31: Multiplexer, De-Multiplexer / Decoders | C31: Th | D31: 1 | E31: 1 | H31: 1 | J31: 1 | K31: 1 | L31: 1 | M31: 1 | N31: 1 | Q31: 1 | V31: 1 | X31: 1 | AA31: =$D31*$E31*J31 -> 1 | AB31: =$D31*$E31*K31 -> 1 | AC31: =$D31*$E31*L31 -> 1 | AD31: =$D31*$E31*M31 -> 1 | AE31: =$D31*$E31*N31 -> 1 | AF31: =$D31*$E31*O31 -> 0 | AG31: =$D31*$E31*P31 -> 0 | AH31: =$D31*$E31*Q31 -> 1 | ... AO31: =$D31*$E31*X31 -> 1 | AQ31: =$D31*$F31*J31 -> 0 | AR31: =$D31*$F31*K31 -> 0 | AS31: =$D31*$F31*L31 -> 0 | AT31: =$D31*$F31*M31 -> 0 | AU31: =$D31*$F31*N31 -> 0 | AV31: =$D31*$F31*O31 -> 0 | AW31: =$D31*$F31*P31 -> 0 | AX31: =$D31*$F31*Q31 -> 0 | ... BE31: =$D31*$F31*X31 -> 0 | BG31: =$D31*$G31*J31 -> 0 | BH31: =$D31*$G31*K31 -> 0 | BI31: =$D31*$G31*L31 -> 0 | BJ31: =$D31*$G31*M31 -> 0 | BK31: =$D31*$G31*N31 -> 0 | BL31: =$D31*$G31*O31 -> 0 | BM31: =$D31*$G31*P31 -> 0 | BN31: =$D31*$G31*Q31 -> 0 | ... BU31: =$D31*$G31*X31 -> 0 | BW31: =$D31*$H31*J31 -> 1 | BX31: =$D31*$H31*K31 -> 1 | BY31: =$D31*$H31*L31 -> 1 | BZ31: =$D31*$H31*M31 -> 1 | CA31: =$D31*$H31*N31 -> 1 | CB31: =$D31*$H31*O31 -> 0 | CC31: =$D31*$H31*P31 -> 0 | CD31: =$D31*$H31*Q31 -> 1 | ... CK31: =$D31*$H31*X31 -> 1 | CM31: =$D31*$I31*J31 -> 0 | CN31: =$D31*$I31*K31 -> 0 | CO31: =$D31*$I31*L31 -> 0 | CP31: =$D31*$I31*M31 -> 0 | CQ31: =$D31*$I31*N31 -> 0 | CR31: =$D31*$I31*O31 -> 0 | CS31: =$D31*$I31*P31 -> 0 | CT31: =$D31*$I31*Q31 -> 0 | ... DA31: =$D31*$I31*X31 -> 0
A32: 4.5 | B32: Adders, Subtractors | C32: Th | D32: 1 | E32: 1 | H32: 1 | J32: 1 | K32: 1 | L32: 1 | M32: 1 | N32: 1 | Q32: 1 | V32: 1 | W32: 1 | AA32: =$D32*$E32*J32 -> 1 | AB32: =$D32*$E32*K32 -> 1 | AC32: =$D32*$E32*L32 -> 1 | AD32: =$D32*$E32*M32 -> 1 | AE32: =$D32*$E32*N32 -> 1 | AF32: =$D32*$E32*O32 -> 0 | AG32: =$D32*$E32*P32 -> 0 | AH32: =$D32*$E32*Q32 -> 1 | ... AO32: =$D32*$E32*X32 -> 0 | AQ32: =$D32*$F32*J32 -> 0 | AR32: =$D32*$F32*K32 -> 0 | AS32: =$D32*$F32*L32 -> 0 | AT32: =$D32*$F32*M32 -> 0 | AU32: =$D32*$F32*N32 -> 0 | AV32: =$D32*$F32*O32 -> 0 | AW32: =$D32*$F32*P32 -> 0 | AX32: =$D32*$F32*Q32 -> 0 | ... BE32: =$D32*$F32*X32 -> 0 | BG32: =$D32*$G32*J32 -> 0 | BH32: =$D32*$G32*K32 -> 0 | BI32: =$D32*$G32*L32 -> 0 | BJ32: =$D32*$G32*M32 -> 0 | BK32: =$D32*$G32*N32 -> 0 | BL32: =$D32*$G32*O32 -> 0 | BM32: =$D32*$G32*P32 -> 0 | BN32: =$D32*$G32*Q32 -> 0 | ... BU32: =$D32*$G32*X32 -> 0 | BW32: =$D32*$H32*J32 -> 1 | BX32: =$D32*$H32*K32 -> 1 | BY32: =$D32*$H32*L32 -> 1 | BZ32: =$D32*$H32*M32 -> 1 | CA32: =$D32*$H32*N32 -> 1 | CB32: =$D32*$H32*O32 -> 0 | CC32: =$D32*$H32*P32 -> 0 | CD32: =$D32*$H32*Q32 -> 1 | ... CK32: =$D32*$H32*X32 -> 0 | CM32: =$D32*$I32*J32 -> 0 | CN32: =$D32*$I32*K32 -> 0 | CO32: =$D32*$I32*L32 -> 0 | CP32: =$D32*$I32*M32 -> 0 | CQ32: =$D32*$I32*N32 -> 0 | CR32: =$D32*$I32*O32 -> 0 | CS32: =$D32*$I32*P32 -> 0 | CT32: =$D32*$I32*Q32 -> 0 | ... DA32: =$D32*$I32*X32 -> 0
A33: 4.6 | B33: BCD Arithmetic, Carry Look Ahead Adder, Serial Adder | C33: Th | D33: 1 | E33: 1 | H33: 1 | J33: 1 | K33: 1 | L33: 1 | M33: 1 | N33: 1 | Q33: 1 | S33: 1 | T33: 1 | V33: 1 | W33: 1 | AA33: =$D33*$E33*J33 -> 1 | AB33: =$D33*$E33*K33 -> 1 | AC33: =$D33*$E33*L33 -> 1 | AD33: =$D33*$E33*M33 -> 1 | AE33: =$D33*$E33*N33 -> 1 | AF33: =$D33*$E33*O33 -> 0 | AG33: =$D33*$E33*P33 -> 0 | AH33: =$D33*$E33*Q33 -> 1 | ... AO33: =$D33*$E33*X33 -> 0 | AQ33: =$D33*$F33*J33 -> 0 | AR33: =$D33*$F33*K33 -> 0 | AS33: =$D33*$F33*L33 -> 0 | AT33: =$D33*$F33*M33 -> 0 | AU33: =$D33*$F33*N33 -> 0 | AV33: =$D33*$F33*O33 -> 0 | AW33: =$D33*$F33*P33 -> 0 | AX33: =$D33*$F33*Q33 -> 0 | ... BE33: =$D33*$F33*X33 -> 0 | BG33: =$D33*$G33*J33 -> 0 | BH33: =$D33*$G33*K33 -> 0 | BI33: =$D33*$G33*L33 -> 0 | BJ33: =$D33*$G33*M33 -> 0 | BK33: =$D33*$G33*N33 -> 0 | BL33: =$D33*$G33*O33 -> 0 | BM33: =$D33*$G33*P33 -> 0 | BN33: =$D33*$G33*Q33 -> 0 | ... BU33: =$D33*$G33*X33 -> 0 | BW33: =$D33*$H33*J33 -> 1 | BX33: =$D33*$H33*K33 -> 1 | BY33: =$D33*$H33*L33 -> 1 | BZ33: =$D33*$H33*M33 -> 1 | CA33: =$D33*$H33*N33 -> 1 | CB33: =$D33*$H33*O33 -> 0 | CC33: =$D33*$H33*P33 -> 0 | CD33: =$D33*$H33*Q33 -> 1 | ... CK33: =$D33*$H33*X33 -> 0 | CM33: =$D33*$I33*J33 -> 0 | CN33: =$D33*$I33*K33 -> 0 | CO33: =$D33*$I33*L33 -> 0 | CP33: =$D33*$I33*M33 -> 0 | CQ33: =$D33*$I33*N33 -> 0 | CR33: =$D33*$I33*O33 -> 0 | CS33: =$D33*$I33*P33 -> 0 | CT33: =$D33*$I33*Q33 -> 0 | ... DA33: =$D33*$I33*X33 -> 0
A34: 4.7 | B34: Digital Comparator, Parity Checker / Generator | C34: Th | D34: 1 | E34: 1 | H34: 1 | J34: 1 | K34: 1 | L34: 1 | M34: 1 | N34: 1 | Q34: 1 | S34: 1 | T34: 1 | U34: 1 | V34: 1 | X34: 1 | AA34: =$D34*$E34*J34 -> 1 | AB34: =$D34*$E34*K34 -> 1 | AC34: =$D34*$E34*L34 -> 1 | AD34: =$D34*$E34*M34 -> 1 | AE34: =$D34*$E34*N34 -> 1 | AF34: =$D34*$E34*O34 -> 0 | AG34: =$D34*$E34*P34 -> 0 | AH34: =$D34*$E34*Q34 -> 1 | ... AO34: =$D34*$E34*X34 -> 1 | AQ34: =$D34*$F34*J34 -> 0 | AR34: =$D34*$F34*K34 -> 0 | AS34: =$D34*$F34*L34 -> 0 | AT34: =$D34*$F34*M34 -> 0 | AU34: =$D34*$F34*N34 -> 0 | AV34: =$D34*$F34*O34 -> 0 | AW34: =$D34*$F34*P34 -> 0 | AX34: =$D34*$F34*Q34 -> 0 | ... BE34: =$D34*$F34*X34 -> 0 | BG34: =$D34*$G34*J34 -> 0 | BH34: =$D34*$G34*K34 -> 0 | BI34: =$D34*$G34*L34 -> 0 | BJ34: =$D34*$G34*M34 -> 0 | BK34: =$D34*$G34*N34 -> 0 | BL34: =$D34*$G34*O34 -> 0 | BM34: =$D34*$G34*P34 -> 0 | BN34: =$D34*$G34*Q34 -> 0 | ... BU34: =$D34*$G34*X34 -> 0 | BW34: =$D34*$H34*J34 -> 1 | BX34: =$D34*$H34*K34 -> 1 | BY34: =$D34*$H34*L34 -> 1 | BZ34: =$D34*$H34*M34 -> 1 | CA34: =$D34*$H34*N34 -> 1 | CB34: =$D34*$H34*O34 -> 0 | CC34: =$D34*$H34*P34 -> 0 | CD34: =$D34*$H34*Q34 -> 1 | ... CK34: =$D34*$H34*X34 -> 1 | CM34: =$D34*$I34*J34 -> 0 | CN34: =$D34*$I34*K34 -> 0 | CO34: =$D34*$I34*L34 -> 0 | CP34: =$D34*$I34*M34 -> 0 | CQ34: =$D34*$I34*N34 -> 0 | CR34: =$D34*$I34*O34 -> 0 | CS34: =$D34*$I34*P34 -> 0 | CT34: =$D34*$I34*Q34 -> 0 | ... DA34: =$D34*$I34*X34 -> 0
A35: 4.8 | B35: Code Converters, Priority Encoders, Decoders / Drivers for Display Devices | C35: Th | D35: 1 | E35: 1 | H35: 1 | J35: 1 | K35: 1 | L35: 1 | M35: 1 | N35: 1 | Q35: 1 | S35: 1 | V35: 1 | X35: 1 | AA35: =$D35*$E35*J35 -> 1 | AB35: =$D35*$E35*K35 -> 1 | AC35: =$D35*$E35*L35 -> 1 | AD35: =$D35*$E35*M35 -> 1 | AE35: =$D35*$E35*N35 -> 1 | AF35: =$D35*$E35*O35 -> 0 | AG35: =$D35*$E35*P35 -> 0 | AH35: =$D35*$E35*Q35 -> 1 | ... AO35: =$D35*$E35*X35 -> 1 | AQ35: =$D35*$F35*J35 -> 0 | AR35: =$D35*$F35*K35 -> 0 | AS35: =$D35*$F35*L35 -> 0 | AT35: =$D35*$F35*M35 -> 0 | AU35: =$D35*$F35*N35 -> 0 | AV35: =$D35*$F35*O35 -> 0 | AW35: =$D35*$F35*P35 -> 0 | AX35: =$D35*$F35*Q35 -> 0 | ... BE35: =$D35*$F35*X35 -> 0 | BG35: =$D35*$G35*J35 -> 0 | BH35: =$D35*$G35*K35 -> 0 | BI35: =$D35*$G35*L35 -> 0 | BJ35: =$D35*$G35*M35 -> 0 | BK35: =$D35*$G35*N35 -> 0 | BL35: =$D35*$G35*O35 -> 0 | BM35: =$D35*$G35*P35 -> 0 | BN35: =$D35*$G35*Q35 -> 0 | ... BU35: =$D35*$G35*X35 -> 0 | BW35: =$D35*$H35*J35 -> 1 | BX35: =$D35*$H35*K35 -> 1 | BY35: =$D35*$H35*L35 -> 1 | BZ35: =$D35*$H35*M35 -> 1 | CA35: =$D35*$H35*N35 -> 1 | CB35: =$D35*$H35*O35 -> 0 | CC35: =$D35*$H35*P35 -> 0 | CD35: =$D35*$H35*Q35 -> 1 | ... CK35: =$D35*$H35*X35 -> 1 | CM35: =$D35*$I35*J35 -> 0 | CN35: =$D35*$I35*K35 -> 0 | CO35: =$D35*$I35*L35 -> 0 | CP35: =$D35*$I35*M35 -> 0 | CQ35: =$D35*$I35*N35 -> 0 | CR35: =$D35*$I35*O35 -> 0 | CS35: =$D35*$I35*P35 -> 0 | CT35: =$D35*$I35*Q35 -> 0 | ... DA35: =$D35*$I35*X35 -> 0
A36: Unit 5 | B36: Sequential circuits and systems | AA36: =$D36*$E36*J36 -> 0 | AB36: =$D36*$E36*K36 -> 0 | AC36: =$D36*$E36*L36 -> 0 | AD36: =$D36*$E36*M36 -> 0 | AE36: =$D36*$E36*N36 -> 0 | AF36: =$D36*$E36*O36 -> 0 | AG36: =$D36*$E36*P36 -> 0 | AH36: =$D36*$E36*Q36 -> 0 | ... AO36: =$D36*$E36*X36 -> 0 | AQ36: =$D36*$F36*J36 -> 0 | AR36: =$D36*$F36*K36 -> 0 | AS36: =$D36*$F36*L36 -> 0 | AT36: =$D36*$F36*M36 -> 0 | AU36: =$D36*$F36*N36 -> 0 | AV36: =$D36*$F36*O36 -> 0 | AW36: =$D36*$F36*P36 -> 0 | AX36: =$D36*$F36*Q36 -> 0 | ... BE36: =$D36*$F36*X36 -> 0 | BG36: =$D36*$G36*J36 -> 0 | BH36: =$D36*$G36*K36 -> 0 | BI36: =$D36*$G36*L36 -> 0 | BJ36: =$D36*$G36*M36 -> 0 | BK36: =$D36*$G36*N36 -> 0 | BL36: =$D36*$G36*O36 -> 0 | BM36: =$D36*$G36*P36 -> 0 | BN36: =$D36*$G36*Q36 -> 0 | ... BU36: =$D36*$G36*X36 -> 0 | BW36: =$D36*$H36*J36 -> 0 | BX36: =$D36*$H36*K36 -> 0 | BY36: =$D36*$H36*L36 -> 0 | BZ36: =$D36*$H36*M36 -> 0 | CA36: =$D36*$H36*N36 -> 0 | CB36: =$D36*$H36*O36 -> 0 | CC36: =$D36*$H36*P36 -> 0 | CD36: =$D36*$H36*Q36 -> 0 | ... CK36: =$D36*$H36*X36 -> 0 | CM36: =$D36*$I36*J36 -> 0 | CN36: =$D36*$I36*K36 -> 0 | CO36: =$D36*$I36*L36 -> 0 | CP36: =$D36*$I36*M36 -> 0 | CQ36: =$D36*$I36*N36 -> 0 | CR36: =$D36*$I36*O36 -> 0 | CS36: =$D36*$I36*P36 -> 0 | CT36: =$D36*$I36*Q36 -> 0 | ... DA36: =$D36*$I36*X36 -> 0
